Workbook

Sheet 概要
A1: 出雲市 介護サービス事業所一覧
A2: 出典：厚生労働省 介護サービス情報公表システム オープンデータ（2025年12月末時点／CC BY 4.0）
A3: 作成：居宅介護支援事業所 しあわせぞうさん ※最新の空き状況・受入可否は各事業所にご確認ください
A5: サービス種別 | B5: 件数 | D5: エリア | E5: 件数
A6: 訪問介護 | B6: =COUNTIF(全事業所!A:A,A6) | D6: 出雲 | E6: =COUNTIF(全事業所!C:C,D6)
A7: 訪問入浴介護 | B7: =COUNTIF(全事業所!A:A,A7) | D7: 平田 | E7: =COUNTIF(全事業所!C:C,D7)
A8: 訪問看護 | B8: =COUNTIF(全事業所!A:A,A8) | D8: 大社 | E8: =COUNTIF(全事業所!C:C,D8)
A9: 訪問リハビリテーション | B9: =COUNTIF(全事業所!A:A,A9) | D9: 斐川 | E9: =COUNTIF(全事業所!C:C,D9)
A10: 通所介護 | B10: =COUNTIF(全事業所!A:A,A10) | D10: 湖陵 | E10: =COUNTIF(全事業所!C:C,D10)
A11: 通所リハビリテーション | B11: =COUNTIF(全事業所!A:A,A11) | D11: 多伎 | E11: =COUNTIF(全事業所!C:C,D11)
A12: 福祉用具貸与 | B12: =COUNTIF(全事業所!A:A,A12) | D12: 佐田 | E12: =COUNTIF(全事業所!C:C,D12)
A13: 短期入所生活介護 | B13: =COUNTIF(全事業所!A:A,A13)
A14: 短期入所療養介護（介護老人保健施設） | B14: =COUNTIF(全事業所!A:A,A14)
A15: 認知症対応型共同生活介護 | B15: =COUNTIF(全事業所!A:A,A15)
A16: 特定施設入居者生活介護（有料老人ホーム） | B16: =COUNTIF(全事業所!A:A,A16)
A17: 特定施設入居者生活介護（軽費老人ホーム） | B17: =COUNTIF(全事業所!A:A,A17)
A18: 特定施設入居者生活介護（有料老人ホーム（サービス付き高齢者向け住宅）） | B18: =COUNTIF(全事業所!A:A,A18)
A19: 特定福祉用具販売 | B19: =COUNTIF(全事業所!A:A,A19)
A20: 居宅介護支援 | B20: =COUNTIF(全事業所!A:A,A20)
A21: 介護老人福祉施設 | B21: =COUNTIF(全事業所!A:A,A21)
A22: 介護老人保健施設 | B22: =COUNTIF(全事業所!A:A,A22)
A23: 地域密着型介護老人福祉施設入所者生活介護 | B23: =COUNTIF(全事業所!A:A,A23)
A24: 介護医療院 | B24: =COUNTIF(全事業所!A:A,A24)
... A30: 地域密着型通所介護 | B30: =COUNTIF(全事業所!A:A,A30)
A31: 合計 | B31: =SUM(B6:B30)

Sheet 全事業所
A1: サービス種別 | B1: 事業所名 | C1: エリア | D1: 住所 | E1: 電話番号 | F1: FAX | G1: 定員 | H1: 営業日 | I1: 運営法人 | J1: 事業所番号 | K1: ホームページ | L1: 料金ページ
A2: 訪問介護 | B2: あおぞら介護センター出雲 | C2: 出雲 | D2: 出雲市下古志町627-2 | E2: 0853-22-0228 | F2: 0853-22-0236 | H2: 平日,土曜日,日曜日,祝日 | I2: 株式会社みのり | J2: 3270401486
A3: 訪問介護 | B3: あんのんの里川跡 | C3: 出雲 | D3: 島根県出雲市荻杼町666-1 | E3: 0853-31-4600 | F3: 0853-31-4601 | H3: 平日,土曜日,日曜日,祝日 | I3: ハート | J3: 3270402112
A4: 訪問介護 | B4: 出雲一畑交通指定訪問介護事業所 | C4: 出雲 | D4: 出雲市常松町353-3 | E4: 0853-21-1149 | F4: 0853-21-2483 | H4: 平日,土曜日 | I4: 出雲一畑交通株式会社 | J4: 3270400793
A5: 訪問介護 | B5: ＮＰＯ法人たすけあい平田 | C5: 平田 | D5: 島根県出雲市西代町１０３２-４ | E5: 0853-62-0257 | F5: 0853-62-0258 | H5: 平日,土曜日 | I5: ＮＰＯ法人たすけあい平田 | J5: 3270300118 | K5: https://tasukeai-hirata.jp
A6: 訪問介護 | B6: 介護ステーション さくら | C6: 出雲 | D6: 矢尾町２７３番地プライム有限会社内プライム有限会社内 | E6: 0853-25-0021 | F6: 0853-25-0020 | H6: 平日,土曜日,日曜日,祝日 | I6: プライム有限会社 | J6: 3270401593 | K6: https://prime-company.jp
A7: 訪問介護 | B7: クレド訪問介護ステーション | C7: 出雲 | D7: 島根県出雲市今市町北本町１丁目１番地セントラルビル２階セントラルビル２階 | E7: 0853-25-7234 | F7: 0853-25-7108 | H7: 平日,土曜日,日曜日,祝日 | I7: 株式会社セントラルビル | J7: 3270403318
A8: 訪問介護 | B8: ケアサポートやわらぎ | C8: 出雲 | D8: 島根県出雲市知井宮町1192-9 | E8: 0853-21-4820 | F8: 0853-21-7280 | H8: 平日,土曜日,日曜日,祝日 | I8: 株式会社ケアステーションやわらぎ | J8: 3270400652
A9: 訪問介護 | B9: ケアステーションにこる | C9: 出雲 | D9: 島根県出雲市渡橋町100 | E9: 0853－27－9196 | F9: 0853－27－9197 | H9: 平日,土曜日,日曜日,祝日 | I9: 合同会社にこる | J9: 3270403276
A10: 訪問介護 | B10: けあビジョンホーム出雲訪問介護 | C10: 斐川 | D10: 島根県出雲市斐川町荘原2320-1 | E10: 0853-73-7111 | F10: 0853-73-7110 | H10: 平日 | I10: 株式会社ビジュアルビジョン | J10: 3270403284
A11: 訪問介護 | B11: ケア・ステーション ピース | C11: 出雲 | D11: 出雲市塩冶町2078-1A102号ララポートララポート | E11: ０８５３－２５－７９１９ | F11: ０８５３－２５－７９２９ | H11: 平日,祝日 | I11: 株式会社空 | J11: 3270402054
A12: 訪問介護 | B12: こうじや訪問介護事業所 | C12: 平田 | D12: 島根県出雲市平田町7429 | E12: 0853-31-4829 | F12: 0853-31-4830 | H12: 平日,土曜日,日曜日,祝日 | I12: 株式会社糀屋 | J12: 3270402831
A13: 訪問介護 | B13: こころねヘルパーステーション今市町 | C13: 出雲 | D13: 島根県出雲市今市町330-5シニアコート今市町・１階シニアコート今市町・１階 | E13: 0853-25-7911 | F13: 0853-30-8811 | H13: 平日,土曜日,日曜日,祝日 | I13: 株式会社シニアリビング・ネクスト | J13: 32A0400028
A14: 訪問介護 | B14: こころねヘルパーステーション塩冶有原町 | C14: 出雲 | D14: 島根県出雲市塩冶有原町5丁目61番地シニアコート塩冶有原町シニアコート塩冶有原町 | E14: 0853-27-9156 | F14: 0853-23-1211 | H14: 平日,土曜日,日曜日,祝日 | I14: 株式会社シニアリビング・ネクスト | J14: 3270403219
A15: 訪問介護 | B15: こころねヘルパーステーション大津新崎 | C15: 出雲 | D15: 島根県出雲市大津新崎町3丁目18番地サービス付き高齢者住宅シニアステージ大津新崎内に併設サービス付き高齢者住宅シニアステージ大津新崎内に併設 | E15: 0853-31-8112 | F15: 0853-23-2780 | H15: 平日,土曜日,日曜日,祝日 | I15: 株式会社サードライフモア | J15: 3270402849
A16: 訪問介護 | B16: こころねヘルパーステーション小山町 | C16: 出雲 | D16: 出雲市小山町503-1 | E16: 0853-31-5563 | F16: 0853-23-7120 | H16: 平日,土曜日,日曜日,祝日 | I16: 株式会社シニアリビング・ネクスト | J16: 3270403391 | K16: https://region-design.co.jp/search/contents/oyama-ss/index.html#pic
A17: 訪問介護 | B17: こころねヘルパーステーション渡橋町 | C17: 出雲 | D17: 島根県出雲市渡橋町346番地シニアコート渡橋町シニアコート渡橋町 | E17: 0853-25-8039 | F17: 0853-23-3501 | H17: 平日,土曜日,日曜日,祝日 | I17: 株式会社シニアリビング・ネクスト | J17: 3270402211
A18: 訪問介護 | B18: サンキ・ウエルビィ介護センター出雲 | C18: 出雲 | D18: 島根県出雲市浜町96-1 | E18: 0853-20-7495 | F18: 0853-20-7497 | H18: 平日,土曜日,日曜日,祝日 | I18: サンキ・ウエルビィ株式会社 | J18: 3270400454
A19: 訪問介護 | B19: CSいずも訪問介護事業所 | C19: 出雲 | D19: 出雲市大津朝倉3-10-3 | E19: 0853-31-4165 | F19: 0853-31-4166 | H19: 平日,土曜日,日曜日,祝日 | I19: 特定非営利活動法人コミュニティサポートいずも | J19: 3270400496 | K19: http://cs-izumo.jp
A20: 訪問介護 | B20: CSいずも訪問介護事業所碧 | C20: 大社 | D20: 島根県出雲市大社町入南80-1 | E20: 0853-31-7010 | F20: 0853-31-7166 | H20: 平日,土曜日,日曜日,祝日 | I20: 特定非営利活動法人コミュニティサポートいずも | J20: 3270403136 | K20: http://cs-izumo.jp/
A21: 訪問介護 | B21: ＪＡしまね斐川介護センター | C21: 斐川 | D21: 島根県出雲市斐川町荘原2172番地3 | E21: 0853-73-9635 | F21: 0853-73-9636 | H21: 平日,土曜日,日曜日,祝日 | I21: 島根県農業協同組合 | J21: 3270402591 | K21: https://ja-shimane.jp/
A22: 訪問介護 | B22: 寿生訪問介護 | C22: 出雲 | D22: 島根県出雲市大津町3627番地22 | E22: 0853-25-9222 | F22: 0853-25-9100 | H22: 平日,土曜日,日曜日,祝日 | I22: 社会福祉法人出雲南福祉会 | J22: 3270402799 | K22: https://www.izumo-minami.jp/
A23: 訪問介護 | B23: 清流園訪問介護事業所 | C23: 出雲 | D23: 出雲市大津町3529番地 | E23: 0853-21-6600 | F23: 0853-24-1118 | H23: 平日,土曜日,日曜日,祝日 | I23: 社会福祉法人 静和会 | J23: 3270400066
A24: 訪問介護 | B24: 第二ことぶき園訪問介護事業所 | C24: 出雲 | D24: 出雲市古志町2105－1 | E24: 0853-20-2686 | F24: 0853-20-2688 | H24: 平日,土曜日,日曜日,祝日 | I24: 社会福祉法人ことぶき福祉会 | J24: 3270400116 | K24: https://kotobuki1071.jimdofree.com
A25: 訪問介護 | B25: デイサービス金太郎の家（訪問介護） | C25: 斐川 | D25: 島根県出雲市斐川町学頭1510番地2 | E25: 0853-31-4832 | F25: 0853-31-4870 | H25: 平日,土曜日,祝日 | I25: 社会福祉法人金太郎の家 | J25: 3270402401 | K25: https://www.kintarounoie.jp/
A26: 訪問介護 | B26: ナカヤ寿楽訪問介護事業所 | C26: 出雲 | D26: 島根県出雲市松寄下町212-3サンフラワー101号室サンフラワー101号室 | E26: 070-7564-3711 | F26: 0853-25-7539 | H26: 平日,土曜日,日曜日,祝日 | I26: 株式会社 ナカヤ | J26: 3270402872 | K26: https://nakaya-juraku.jp
A27: 訪問介護 | B27: 西出雲ヘルパーステーション | C27: 出雲 | D27: 島根県 出雲市 東園町725-3サービス付き高齢者向け住宅ふりーぷらす東園内サービス付き高齢者向け住宅ふりーぷらす東園内 | E27: 0853-25-8781 | F27: 0853-25-8782 | H27: 平日,土曜日,日曜日,祝日 | I27: 株式会社ソーシャルプランニングネットワーク | J27: 3270402724
A28: 訪問介護 | B28: ニチイケアセンター出雲 | C28: 出雲 | D28: 出雲市大津朝倉3丁目4-5 | E28: 0853-20-7377 | F28: 0853-20-7380 | H28: 平日,土曜日,日曜日,祝日 | I28: 株式会社ニチイ学館 | J28: 3270400199 | K28: https://www.nichiigakkan.co.jp
A29: 訪問介護 | B29: ﾆﾁｲｹｱｾﾝﾀｰ出雲みなみ | C29: 出雲 | D29: 島根県出雲市天神町869番地天神ﾋﾞﾙ3Ｆ 303号室天神ﾋﾞﾙ3Ｆ 303号室 | E29: 0853-24-7671 | F29: 0853-23-8110 | H29: 平日,土曜日,日曜日,祝日 | I29: 株式会社ニチイ学館 | J29: 3270402070 | K29: https://www.nichiigakkan.co.jp
A30: 訪問介護 | B30: ニチイケアセンター斐川 | C30: 斐川 | D30: 島根県出雲市斐川町直江4914-7小澤ビル2Ｆ東小澤ビル2Ｆ東 | E30: 0853-73-7025 | F30: 0853-72-8980 | H30: 平日,土曜日,日曜日,祝日 | I30: 株式会社ニチイ学館 | J30: 3270403128 | K30: https://www.nichiigakkan.co.jp
A31: 訪問介護 | B31: 花水木 | C31: 平田 | D31: 島根県出雲市灘分町７８６番地１ | E31: 0853-63-5031 | F31: 0853-63-4627 | H31: 平日,土曜日,日曜日,祝日 | I31: ひらた福祉会 | J31: 3270401569 | K31: https://hirahuku.com
A32: 訪問介護 | B32: ひかわ生協ヘルパーステーション あおぞら | C32: 斐川 | D32: 島根県出雲市斐川町美南1505番地1 | E32: 0853-73-3555 | F32: 0853-72-7534 | H32: 平日,土曜日,日曜日,祝日 | I32: ひかわ医療生活協同組合 | J32: 3271600375 | K32: https://www.hikawa-hp.com
A33: 訪問介護 | B33: ひまわり園ホームヘルプステーション | C33: 出雲 | D33: 出雲市神西沖町2513-8 | E33: 0853-43-3528 | F33: 0853-43-2747 | H33: 平日,土曜日,祝日 | I33: 社会福祉法人ひまわり福祉会 | J33: 3270400272
A34: 訪問介護 | B34: ふれあいサービスごうばら訪問介護事業所 | C34: 平田 | D34: 出雲市平田町1816-15 | E34: 0853-62-9901 | F34: 0853-62-9908 | H34: 平日,土曜日,日曜日,祝日 | I34: 有限会社ごうばら | J34: 3270400918
A35: 訪問介護 | B35: ヘルパーステーション ひまり | C35: 出雲 | D35: 島根県出雲市馬木町２２４－１ | E35: ０８５３－４８－９０５８ | F35: ０８５３－４８－００４７ | H35: 平日,土曜日,日曜日,祝日 | I35: 株式会社ひまり | J35: 3270402930
A36: 訪問介護 | B36: ヘルパーステーション ふるさと苑 | C36: 大社 | D36: 出雲市大社町中荒木1745-2 | E36: 0853-53-6703 | F36: 0853-53-6701 | H36: 平日,土曜日,日曜日,祝日 | I36: 社会福祉法人まほろばの郷 | J36: 3271600276 | K36: https://www.sunlight.or.jp
A37: 訪問介護 | B37: ヘルパステーション花鈴 | C37: 平田 | D37: 島根県出雲市美野町504 | E37: 0583-67-0222 | F37: 0853-67-9181 | H37: 平日 | I37: 有限会社伊野本陣 | J37: 3270403151 | K37: http://inohonjin.jp/
A38: 訪問介護 | B38: ヘルパーステーションすずらん | C38: 出雲 | D38: 島根県出雲市塩冶神前６丁目１番８号Ａ－１０２ | E38: 0853-24-7717 | F38: 0853-30-0538 | H38: 平日,土曜日,日曜日,祝日 | I38: コニファー株式会社 | J38: 3270401726
A39: 訪問介護 | B39: ヘルパーステーションパーパス | C39: 出雲 | D39: 出雲市姫原2-3-13かねつきマンション102かねつきマンション102 | E39: 0853-25-7835 | F39: 0853-25-7836 | H39: 平日,土曜日,日曜日,祝日 | I39: 株式会社パーパス | J39: 3270403268 | K39: https://pur-pose.jp/
A40: 訪問介護 | B40: 訪問介護 グッドライフ | C40: 出雲 | D40: 塩冶善行町14-3 | E40: 0853-27-9991 | F40: 0853-27-9992 | H40: 平日,土曜日,日曜日,祝日 | I40: 株式会社 コスモス | J40: 3270402161 | K40: https://www.cosmos-izumo.jp
...

Sheet 訪問介護
A1: 訪問介護（出雲市・54件）
A2: 事業所名 | B2: エリア | C2: 住所 | D2: 電話番号 | E2: FAX | F2: 定員 | G2: 営業日 | H2: 運営法人 | I2: 事業所番号 | J2: ホームページ | K2: 料金ページ
A3: あおぞら介護センター出雲 | B3: 出雲 | C3: 出雲市下古志町627-2 | D3: 0853-22-0228 | E3: 0853-22-0236 | G3: 平日,土曜日,日曜日,祝日 | H3: 株式会社みのり | I3: 3270401486
A4: あんのんの里川跡 | B4: 出雲 | C4: 島根県出雲市荻杼町666-1 | D4: 0853-31-4600 | E4: 0853-31-4601 | G4: 平日,土曜日,日曜日,祝日 | H4: ハート | I4: 3270402112
A5: 出雲一畑交通指定訪問介護事業所 | B5: 出雲 | C5: 出雲市常松町353-3 | D5: 0853-21-1149 | E5: 0853-21-2483 | G5: 平日,土曜日 | H5: 出雲一畑交通株式会社 | I5: 3270400793
A6: ＮＰＯ法人たすけあい平田 | B6: 平田 | C6: 島根県出雲市西代町１０３２-４ | D6: 0853-62-0257 | E6: 0853-62-0258 | G6: 平日,土曜日 | H6: ＮＰＯ法人たすけあい平田 | I6: 3270300118 | J6: https://tasukeai-hirata.jp
A7: 介護ステーション さくら | B7: 出雲 | C7: 矢尾町２７３番地プライム有限会社内プライム有限会社内 | D7: 0853-25-0021 | E7: 0853-25-0020 | G7: 平日,土曜日,日曜日,祝日 | H7: プライム有限会社 | I7: 3270401593 | J7: https://prime-company.jp
A8: クレド訪問介護ステーション | B8: 出雲 | C8: 島根県出雲市今市町北本町１丁目１番地セントラルビル２階セントラルビル２階 | D8: 0853-25-7234 | E8: 0853-25-7108 | G8: 平日,土曜日,日曜日,祝日 | H8: 株式会社セントラルビル | I8: 3270403318
A9: ケアサポートやわらぎ | B9: 出雲 | C9: 島根県出雲市知井宮町1192-9 | D9: 0853-21-4820 | E9: 0853-21-7280 | G9: 平日,土曜日,日曜日,祝日 | H9: 株式会社ケアステーションやわらぎ | I9: 3270400652
A10: ケアステーションにこる | B10: 出雲 | C10: 島根県出雲市渡橋町100 | D10: 0853－27－9196 | E10: 0853－27－9197 | G10: 平日,土曜日,日曜日,祝日 | H10: 合同会社にこる | I10: 3270403276
A11: けあビジョンホーム出雲訪問介護 | B11: 斐川 | C11: 島根県出雲市斐川町荘原2320-1 | D11: 0853-73-7111 | E11: 0853-73-7110 | G11: 平日 | H11: 株式会社ビジュアルビジョン | I11: 3270403284
A12: ケア・ステーション ピース | B12: 出雲 | C12: 出雲市塩冶町2078-1A102号ララポートララポート | D12: ０８５３－２５－７９１９ | E12: ０８５３－２５－７９２９ | G12: 平日,祝日 | H12: 株式会社空 | I12: 3270402054
A13: こうじや訪問介護事業所 | B13: 平田 | C13: 島根県出雲市平田町7429 | D13: 0853-31-4829 | E13: 0853-31-4830 | G13: 平日,土曜日,日曜日,祝日 | H13: 株式会社糀屋 | I13: 3270402831
A14: こころねヘルパーステーション今市町 | B14: 出雲 | C14: 島根県出雲市今市町330-5シニアコート今市町・１階シニアコート今市町・１階 | D14: 0853-25-7911 | E14: 0853-30-8811 | G14: 平日,土曜日,日曜日,祝日 | H14: 株式会社シニアリビング・ネクスト | I14: 32A0400028
A15: こころねヘルパーステーション塩冶有原町 | B15: 出雲 | C15: 島根県出雲市塩冶有原町5丁目61番地シニアコート塩冶有原町シニアコート塩冶有原町 | D15: 0853-27-9156 | E15: 0853-23-1211 | G15: 平日,土曜日,日曜日,祝日 | H15: 株式会社シニアリビング・ネクスト | I15: 3270403219
A16: こころねヘルパーステーション大津新崎 | B16: 出雲 | C16: 島根県出雲市大津新崎町3丁目18番地サービス付き高齢者住宅シニアステージ大津新崎内に併設サービス付き高齢者住宅シニアステージ大津新崎内に併設 | D16: 0853-31-8112 | E16: 0853-23-2780 | G16: 平日,土曜日,日曜日,祝日 | H16: 株式会社サードライフモア | I16: 3270402849
A17: こころねヘルパーステーション小山町 | B17: 出雲 | C17: 出雲市小山町503-1 | D17: 0853-31-5563 | E17: 0853-23-7120 | G17: 平日,土曜日,日曜日,祝日 | H17: 株式会社シニアリビング・ネクスト | I17: 3270403391 | J17: https://region-design.co.jp/search/contents/oyama-ss/index.html#pic
A18: こころねヘルパーステーション渡橋町 | B18: 出雲 | C18: 島根県出雲市渡橋町346番地シニアコート渡橋町シニアコート渡橋町 | D18: 0853-25-8039 | E18: 0853-23-3501 | G18: 平日,土曜日,日曜日,祝日 | H18: 株式会社シニアリビング・ネクスト | I18: 3270402211
A19: サンキ・ウエルビィ介護センター出雲 | B19: 出雲 | C19: 島根県出雲市浜町96-1 | D19: 0853-20-7495 | E19: 0853-20-7497 | G19: 平日,土曜日,日曜日,祝日 | H19: サンキ・ウエルビィ株式会社 | I19: 3270400454
A20: CSいずも訪問介護事業所 | B20: 出雲 | C20: 出雲市大津朝倉3-10-3 | D20: 0853-31-4165 | E20: 0853-31-4166 | G20: 平日,土曜日,日曜日,祝日 | H20: 特定非営利活動法人コミュニティサポートいずも | I20: 3270400496 | J20: http://cs-izumo.jp
A21: CSいずも訪問介護事業所碧 | B21: 大社 | C21: 島根県出雲市大社町入南80-1 | D21: 0853-31-7010 | E21: 0853-31-7166 | G21: 平日,土曜日,日曜日,祝日 | H21: 特定非営利活動法人コミュニティサポートいずも | I21: 3270403136 | J21: http://cs-izumo.jp/
A22: ＪＡしまね斐川介護センター | B22: 斐川 | C22: 島根県出雲市斐川町荘原2172番地3 | D22: 0853-73-9635 | E22: 0853-73-9636 | G22: 平日,土曜日,日曜日,祝日 | H22: 島根県農業協同組合 | I22: 3270402591 | J22: https://ja-shimane.jp/
A23: 寿生訪問介護 | B23: 出雲 | C23: 島根県出雲市大津町3627番地22 | D23: 0853-25-9222 | E23: 0853-25-9100 | G23: 平日,土曜日,日曜日,祝日 | H23: 社会福祉法人出雲南福祉会 | I23: 3270402799 | J23: https://www.izumo-minami.jp/
A24: 清流園訪問介護事業所 | B24: 出雲 | C24: 出雲市大津町3529番地 | D24: 0853-21-6600 | E24: 0853-24-1118 | G24: 平日,土曜日,日曜日,祝日 | H24: 社会福祉法人 静和会 | I24: 3270400066
A25: 第二ことぶき園訪問介護事業所 | B25: 出雲 | C25: 出雲市古志町2105－1 | D25: 0853-20-2686 | E25: 0853-20-2688 | G25: 平日,土曜日,日曜日,祝日 | H25: 社会福祉法人ことぶき福祉会 | I25: 3270400116 | J25: https://kotobuki1071.jimdofree.com
A26: デイサービス金太郎の家（訪問介護） | B26: 斐川 | C26: 島根県出雲市斐川町学頭1510番地2 | D26: 0853-31-4832 | E26: 0853-31-4870 | G26: 平日,土曜日,祝日 | H26: 社会福祉法人金太郎の家 | I26: 3270402401 | J26: https://www.kintarounoie.jp/
A27: ナカヤ寿楽訪問介護事業所 | B27: 出雲 | C27: 島根県出雲市松寄下町212-3サンフラワー101号室サンフラワー101号室 | D27: 070-7564-3711 | E27: 0853-25-7539 | G27: 平日,土曜日,日曜日,祝日 | H27: 株式会社 ナカヤ | I27: 3270402872 | J27: https://nakaya-juraku.jp
A28: 西出雲ヘルパーステーション | B28: 出雲 | C28: 島根県 出雲市 東園町725-3サービス付き高齢者向け住宅ふりーぷらす東園内サービス付き高齢者向け住宅ふりーぷらす東園内 | D28: 0853-25-8781 | E28: 0853-25-8782 | G28: 平日,土曜日,日曜日,祝日 | H28: 株式会社ソーシャルプランニングネットワーク | I28: 3270402724
A29: ニチイケアセンター出雲 | B29: 出雲 | C29: 出雲市大津朝倉3丁目4-5 | D29: 0853-20-7377 | E29: 0853-20-7380 | G29: 平日,土曜日,日曜日,祝日 | H29: 株式会社ニチイ学館 | I29: 3270400199 | J29: https://www.nichiigakkan.co.jp
A30: ﾆﾁｲｹｱｾﾝﾀｰ出雲みなみ | B30: 出雲 | C30: 島根県出雲市天神町869番地天神ﾋﾞﾙ3Ｆ 303号室天神ﾋﾞﾙ3Ｆ 303号室 | D30: 0853-24-7671 | E30: 0853-23-8110 | G30: 平日,土曜日,日曜日,祝日 | H30: 株式会社ニチイ学館 | I30: 3270402070 | J30: https://www.nichiigakkan.co.jp
A31: ニチイケアセンター斐川 | B31: 斐川 | C31: 島根県出雲市斐川町直江4914-7小澤ビル2Ｆ東小澤ビル2Ｆ東 | D31: 0853-73-7025 | E31: 0853-72-8980 | G31: 平日,土曜日,日曜日,祝日 | H31: 株式会社ニチイ学館 | I31: 3270403128 | J31: https://www.nichiigakkan.co.jp
A32: 花水木 | B32: 平田 | C32: 島根県出雲市灘分町７８６番地１ | D32: 0853-63-5031 | E32: 0853-63-4627 | G32: 平日,土曜日,日曜日,祝日 | H32: ひらた福祉会 | I32: 3270401569 | J32: https://hirahuku.com
A33: ひかわ生協ヘルパーステーション あおぞら | B33: 斐川 | C33: 島根県出雲市斐川町美南1505番地1 | D33: 0853-73-3555 | E33: 0853-72-7534 | G33: 平日,土曜日,日曜日,祝日 | H33: ひかわ医療生活協同組合 | I33: 3271600375 | J33: https://www.hikawa-hp.com
A34: ひまわり園ホームヘルプステーション | B34: 出雲 | C34: 出雲市神西沖町2513-8 | D34: 0853-43-3528 | E34: 0853-43-2747 | G34: 平日,土曜日,祝日 | H34: 社会福祉法人ひまわり福祉会 | I34: 3270400272
A35: ふれあいサービスごうばら訪問介護事業所 | B35: 平田 | C35: 出雲市平田町1816-15 | D35: 0853-62-9901 | E35: 0853-62-9908 | G35: 平日,土曜日,日曜日,祝日 | H35: 有限会社ごうばら | I35: 3270400918
A36: ヘルパーステーション ひまり | B36: 出雲 | C36: 島根県出雲市馬木町２２４－１ | D36: ０８５３－４８－９０５８ | E36: ０８５３－４８－００４７ | G36: 平日,土曜日,日曜日,祝日 | H36: 株式会社ひまり | I36: 3270402930
A37: ヘルパーステーション ふるさと苑 | B37: 大社 | C37: 出雲市大社町中荒木1745-2 | D37: 0853-53-6703 | E37: 0853-53-6701 | G37: 平日,土曜日,日曜日,祝日 | H37: 社会福祉法人まほろばの郷 | I37: 3271600276 | J37: https://www.sunlight.or.jp
A38: ヘルパステーション花鈴 | B38: 平田 | C38: 島根県出雲市美野町504 | D38: 0583-67-0222 | E38: 0853-67-9181 | G38: 平日 | H38: 有限会社伊野本陣 | I38: 3270403151 | J38: http://inohonjin.jp/
A39: ヘルパーステーションすずらん | B39: 出雲 | C39: 島根県出雲市塩冶神前６丁目１番８号Ａ－１０２ | D39: 0853-24-7717 | E39: 0853-30-0538 | G39: 平日,土曜日,日曜日,祝日 | H39: コニファー株式会社 | I39: 3270401726
A40: ヘルパーステーションパーパス | B40: 出雲 | C40: 出雲市姫原2-3-13かねつきマンション102かねつきマンション102 | D40: 0853-25-7835 | E40: 0853-25-7836 | G40: 平日,土曜日,日曜日,祝日 | H40: 株式会社パーパス | I40: 3270403268 | J40: https://pur-pose.jp/
...

Sheet 訪問入浴介護
A1: 訪問入浴介護（出雲市・3件）
A2: 事業所名 | B2: エリア | C2: 住所 | D2: 電話番号 | E2: FAX | F2: 定員 | G2: 営業日 | H2: 運営法人 | I2: 事業所番号 | J2: ホームページ | K2: 料金ページ
A3: あすなろ訪問入浴介護事業所 | B3: 出雲 | C3: 出雲市白枝町395-2 | D3: 0853-23-0078 | E3: 0853-23-8544 | G3: 平日,祝日 | H3: 社会福祉法人 あすなろ会 | I3: 3270400363
A4: いなさ園訪問入浴介護事業所 | B4: 大社 | C4: 出雲市大社町杵築西１６４３番地２ | D4: 0853-53-5727 | E4: 0853-53-5025 | F4: 30 | G4: 平日 | H4: 社会福祉法人きづき会 | I4: 3271600227 | J4: http://www.kidukikai.or.jp
A5: ＪＡしまね斐川介護センター | B5: 斐川 | C5: 島根県出雲市斐川町荘原2172番地3 | D5: 0853-73-9635 | E5: 0853-73-9636 | G5: 平日 | H5: 島根県農業協同組合 | I5: 3270402609 | J5: https://ja-shimane.jp/

Sheet 訪問看護
A1: 訪問看護（出雲市・33件）
A2: 事業所名 | B2: エリア | C2: 住所 | D2: 電話番号 | E2: FAX | F2: 定員 | G2: 営業日 | H2: 運営法人 | I2: 事業所番号 | J2: ホームページ | K2: 料金ページ
A3: 出雲看護サービスセンター | B3: 出雲 | C3: 出雲市今市町新町827-21 | D3: 0853-24-2800 | E3: 0853-24-2802 | G3: 平日 | H3: 出雲医療生活協同組合 | I3: 3260490002 | J3: https://izumo-hewcoop.jp/
A4: 出雲市立総合医療センター 訪問看護ステーション | B4: 平田 | C4: 島根県出雲市灘分町613番地 | D4: 0853-63-5117 | E4: 0853-63-5121 | G4: 平日 | I4: 3260490234 | J4: https://www.izumocity-hp.jp
A5: 出雲徳洲会 訪問看護ステーション | B5: 斐川 | C5: 島根県出雲市斐川町直江3964-1 | D5: 0853-73-7792 | E5: 0853-88-0830 | G5: 平日,祝日 | H5: 医療法人徳洲会 | I5: 3260490242 | J5: https://www.izumo-tokushukai.jp/homevisit/
A6: 出雲徳洲会病院 訪問看護サービス 虹 | B6: 斐川 | C6: 島根県出雲市斐川町直江3964-1 | D6: 0853-73-7793 | E6: 0853-88-0830 | G6: 平日,土曜日,祝日 | H6: 医療法人 沖縄徳洲会 | I6: 3211610989 | J6: https://www.izumo-tokushukai.jp/
A7: いなさ園訪問看護ステーション | B7: 大社 | C7: 島根県出雲市大社町杵築西１６４３番地２ | D7: 0853-53-5089 | E7: 0853-53-5025 | G7: 平日 | H7: 社会福祉法人きづき会 | I7: 3260490069 | J7: http://www.kidukikai.or.jp
A8: 医療法人 古瀬医院 | B8: 出雲 | C8: 島根県出雲市稗原町2490-3 | D8: 0853-48-0008 | E8: 0853-48-1404 | G8: 平日 | H8: 医療法人 古瀬医院 | I8: 3210411215 | J8: https://www.furuse-clinic.jp/
A9: クレド訪問看護リハビリステーション | B9: 出雲 | C9: 島根県出雲市今市町北本町１丁目１番地 | D9: 0853-25-7267 | E9: 0853-25-7108 | G9: 平日,祝日 | H9: 株式会社セントラルビル | I9: 3260490200
A10: Grow訪問看護ステーション | B10: 出雲 | C10: 島根県出雲市塩谷町南町3-6-5マンリョウアパート101号室マンリョウアパート101号室 | D10: 0853-27-9870 | E10: 0853-27-9860 | G10: 平日,祝日 | H10: 株式会社ＬＩＦＥ ＣＲＥＡＴＥ | I10: 3260490267
A11: こころね訪問看護ステーション今市町 | B11: 出雲 | C11: 島根県出雲市今市町330-5シニアコート今市町内1階シニアコート今市町内1階 | D11: 0853-25-8838 | E11: 0853-23-8811 | G11: 平日,土曜日,日曜日,祝日 | H11: 株式会社シニアリビング・ネクスト | I11: 3260490192
A12: こころね訪問看護ステーション塩冶有原町 | B12: 出雲 | C12: 島根県出雲市塩冶有原町5丁目61番地シニアコート塩冶有原町シニアコート塩冶有原町 | D12: 0853-25-9438 | E12: 0853-23-1211 | G12: 平日,土曜日,日曜日,祝日 | H12: 株式会社シニアリビング・ネクスト | I12: 3260490218
A13: こころね訪問看護ステーション大津新崎 | B13: 出雲 | C13: 島根県出雲市大津新崎町3丁目18番地シニアステージ大津新崎シニアステージ大津新崎 | D13: 0853-31-8223 | E13: 0853-23-2780 | G13: 平日,土曜日,日曜日,祝日 | H13: 株式会社サードライフモア | I13: 3260490168
A14: こころね訪問看護ステーション渡橋町 | B14: 出雲 | C14: 出雲市渡橋町346番地シニアコート渡橋町シニアコート渡橋町 | D14: 0853-25-8122 | E14: 0853-23-3501 | G14: 平日,土曜日,日曜日,祝日 | H14: 株式会社シニアリビング・ネクスト | I14: 3260490101
A15: こころ訪問看護ステーション | B15: 出雲 | C15: 島根県出雲市天神町１１５番地２ | D15: ０８５３-２２-８８７５ | E15: ０８５３-２７-９１１４ | F15: 5 | G15: 平日,土曜日 | H15: 合同会社クオリティ・オブ・ライフ | I15: 3260490127
A16: コミケア在宅看護センター出雲 | B16: 出雲 | C16: 島根県出雲市大津町2069-1 | D16: 0853-31-5237 | E16: 0853-31-5238 | F16: 90 | G16: 平日 | H16: 株式会社Ｃｏｍｍｕｎｉｔｙ Ｃａｒｅ | I16: 3260490325 | J16: https://comcare.shimane.jp/
A17: サンキ・ウエルビィ訪問看護ステーション大社 | B17: 大社 | C17: 島根県出雲市大社町北荒木1313小規模多機能センター出雲と併設小規模多機能センター出雲と併設 | D17: 0853-25-8750 | E17: 0853-53-8117 | F17: 5 | G17: 平日 | H17: サンキ・ウエルビィ株式会社 | I17: 3260490275
A18: 在宅診療所いずも | B18: 出雲 | C18: 下古志町７１３－１ | D18: 0853-24-8151 | E18: 0853-24-8152 | G18: 平日,土曜日,日曜日,祝日 | H18: 医療法人つたや会 | I18: 3210412775 | J18: https://www.medicalco-tsutaya.jp/
A19: 島根県看護協会訪問看護ステーションいずも | B19: 出雲 | C19: 島根県出雲市姫原1丁目7-14 | D19: 0853-24-1774 | E19: 0853-24-1792 | G19: 平日 | H19: 公益社団法人島根県看護協会 | I19: 3260490028 | J19: https://www.shimane-kango.or.jp/general/station/229/1061
A20: 寿生訪問看護ステーション | B20: 出雲 | C20: 島根県出雲市上塩冶町2862番地1寿生病院寿生病院 | D20: 0853-25-9333 | E20: 0853-25-9336 | F20: 50 | G20: 平日,祝日 | H20: 医療法人壽生会 | I20: 3260490317 | J20: http://juseikai.jp
A21: 須谷医院 | B21: 出雲 | C21: 島根県出雲市所原町６０ | D21: 0853-48-0210 | E21: 0853-48-2525 | G21: 平日,土曜日 | H21: 須谷医院 | I21: 3210411488
A22: つばさ訪問看護ステーション | B22: 出雲 | C22: 島根県出雲市武志町1020番地4 | D22: 0853-31-5260 | E22: 0853-31-5503 | G22: 平日,土曜日 | H22: ＮＰＯ法人アズイット出雲 | I22: 3260490333
A23: 特定非営利活動法人 訪問看護ステーションほほえみ | B23: 平田 | C23: 島根県出雲市平田町7178 | D23: 0853-63-5810 | E23: 0853-63-5822 | G23: 平日,土曜日,祝日 | H23: 特定非営利活動法人訪問看護ステーションほほえみ | I23: 3260490085
A24: ナカヤ寿楽 訪問看護ステーション | B24: 出雲 | C24: 島根県出雲市荒茅町2466 アリスA棟 101号 | D24: 0853-31-8200 | E24: 0853-31-8201 | G24: 平日,祝日 | H24: 株式会社ナカヤ | I24: 3260490309 | J24: https://nakaya-juraku.jp/
A25: なぎ訪問看護ステーション | B25: 出雲 | C25: 島根県出雲市知井宮町1223-2 | D25: 0853-25-8764 | E25: 0853-25-8540 | G25: 平日,祝日 | H25: 合同会社 凪 | I25: 3260490283
A26: ひかわ生協訪問看護ステーション チューリップ | B26: 斐川 | C26: 島根県出雲市斐川町美南1507番地1 | D26: 0853-72-7532 | E26: 0853-72-7534 | G26: 平日,土曜日 | H26: ひかわ医療生活協同組合 | I26: 3261690006 | J26: https://www.hikawa-hp.com
A27: 斐川訪問看護ステーションさくら | B27: 斐川 | C27: 島根県出雲市斐川町上直江１４７２ー１ | D27: （0853）72-7008 | E27: （0853）72-7846 | G27: 平日,祝日 | H27: 一般社団法人さくら | I27: 3260490291
A28: 深田医院 | B28: 出雲 | C28: 出雲市高岡町53-1 | D28: 0853-22-8824 | E28: 0853-22-9030 | G28: 平日 | H28: 深田医院 | I28: 3210411983
A29: 訪問看護ステーション kahana | B29: 出雲 | C29: 島根県出雲市天神町888-2ラポール天神101ラポール天神101 | D29: 0853315820 | E29: 0853315821 | G29: 平日 | H29: 合同会社ｋａｈａｎａ | I29: 3260490341
A30: 訪問看護ステーション クローバー | B30: 出雲 | C30: 島根県出雲市今市町藤ケ森2074 | D30: 0853-25-7704 | E30: 0853-25-7870 | G30: 平日 | H30: 医療法人江田クリニック | I30: 3260490259
A31: 特定非営利活動法人訪問看護ステーション愛 | B31: 平田 | C31: 出雲市国富町1015番地 | D31: 0853-62-3180 | E31: 0853-62-3265 | G31: 平日,土曜日,日曜日,祝日 | H31: 特定非営利活動法人訪問看護ステーション愛 | I31: 3260390012
A32: 訪問看護ステーションこりょう | B32: 湖陵 | C32: 出雲市湖陵町二部1802番地3 | D32: 0853-43-3238 | E32: 0853-43-3252 | G32: 平日 | H32: 特定非営利活動法人訪問看護ステーションこりょう | I32: 3260490077
A33: 訪問看護ステーション彩雲 | B33: 出雲 | C33: 島根県出雲市高岡町388-1 | D33: 0853-25-8844 | E33: 0853-25-8845 | G33: 平日 | H33: 株式会社 ラッシュ | I33: 3260490226 | J33: https://lush-care.jp/
A34: 訪問看護ステーションたき | B34: 多伎 | C34: 出雲市多伎町小田５０番地７ | D34: 0853-86-2975 | E34: 0853-86-2978 | F34: 40 | G34: 平日 | H34: 社会福祉法人多伎の郷 | I34: 3261690030
A35: 訪問看護ステーションRelisa | B35: 出雲 | C35: 島根県出雲市武志町182-3 | D35: 0853-25-8601 | E35: 0853-25-8603 | G35: 平日 | H35: 株式会社ＲＥＴＩＣＥ | I35: 3260490135

Sheet 訪問リハビリテーション
A1: 訪問リハビリテーション（出雲市・16件）
A2: 事業所名 | B2: エリア | C2: 住所 | D2: 電話番号 | E2: FAX | F2: 定員 | G2: 営業日 | H2: 運営法人 | I2: 事業所番号 | J2: ホームページ | K2: 料金ページ
A3: 出雲市民リハビリテーション病院 | B3: 出雲 | C3: 島根県出雲市知井宮町238 | D3: 0853-21-2733 | E3: 0853-24-2906 | G3: 平日 | H3: 出雲医療生活協同組合 | I3: 3210412536 | J3: https://izumo-hewcoop.jp/izumoriha-hp/
A4: 出雲市立総合医療センター | B4: 平田 | C4: 島根県出雲市灘分町６１３番地 | D4: 0853-63-5111 | E4: 0853-63-4228 | G4: 平日 | I4: 3210310011 | J4: https://www.izumocity-hp.jp
A5: 出雲徳洲会病院 | B5: 斐川 | C5: 出雲市斐川町直江3964-1 | D5: 0853-73-7000 | E5: 0853-73-7077 | G5: 平日,祝日 | H5: 医療法人徳洲会 | I5: 3211610989 | J5: https://www.izumo-tokushukai.jp/
A6: 医療法人かんど会 クリニックかんど | B6: 出雲 | C6: 島根県出雲市西新町二丁目2457-7 | D6: 0853-25-2552 | E6: 0853-25-2553 | F6: 140 | G6: 平日 | H6: 医療法人かんど会 | I6: 3210412569 | J6: http://www.kandokai.jp/clinic/
A7: 医療法人社団岡倉会 高鳥クリニック | B7: 出雲 | C7: 島根県出雲市武志町７３４－１ | D7: 0853-20-1338 | E7: 0853-24-8515 | G7: 平日 | H7: 医療法人社団岡倉会 | I7: 3210411827
A8: 医療法人社団林整形外科医院 | B8: 出雲 | C8: 姫原町１１４－３ | D8: ０８５３－２１－１７５８ | E8: ０８５３－２１－０８１１ | G8: 平日 | H8: 林整形外科医院 | I8: 3210411223 | J8: http://hayashiseikei.c.ooco.jp/
A9: えだクリニック整形外科リハビリテーション科 | B9: 出雲 | C9: 島根県出雲市今市町藤ヶ森2074 | D9: 0853-31-5515 | E9: 0853-31-5516 | F9: 550 | G9: 平日 | H9: 医療法人江田クリニック | I9: 3210412759 | J9: https://izumo.edaclinic.jp/
A10: 大曲診療所 | B10: 出雲 | C10: 島根県出雲市大津町1941 | D10: 0853-21-1738 | E10: 0853-21-8900 | G10: 平日 | H10: 出雲医療生活協同組合 | I10: 3210412544 | J10: https://izumo-hewcoop.jp/oomagari/
A11: 介護老人保健施設 出雲徳洲苑 | B11: 斐川 | C11: 島根県出雲市斐川町直江3964-1 | D11: 0853-73-7577 | E11: 0853-73-7570 | G11: 平日 | H11: 医療法人徳洲会 | I11: 3250480088 | J11: https://izumo-tokushuen.com/
A12: 介護老人保健施設 もくもく | B12: 出雲 | C12: 江田町278番地 | D12: 0853-24-6001 | E12: 0853-24-6621 | G12: 平日,祝日 | H12: 社会福祉法人 おおつか福祉会 | I12: 3250480047
A13: 寿生苑 訪問リハビリテーション | B13: 出雲 | C13: 島根県出雲市上塩冶町2862-1 | D13: 0853-25-0088 | E13: 0853-25-0240 | G13: 平日 | H13: 壽生会 | I13: 3250480021 | J13: http://juseikai.jp/
A14: ひかわ医療生活協同組合 斐川生協病院 訪問リハビリテーションゆぃ | B14: 斐川 | C14: 出雲市斐川町美南1507番地1 | D14: 0853-73-8708 | E14: 0853-72-7534 | G14: 平日,土曜日 | H14: ひかわ医療生活協同組合 | I14: 3211610922 | J14: https://www.hikawa-hp.com
A15: 深田医院 | B15: 出雲 | C15: 出雲市高岡町53-1 | D15: 0853-22-8824 | E15: 0853-22-9030 | G15: 平日,土曜日 | H15: 深田医院 | I15: 3210411983
A16: 訪問リハビリテーション事業所まんだ | B16: 平田 | C16: 島根県出雲市万田町535番地１ | D16: 0853-63-5610 | E16: 0853-63-5612 | F16: 10 | G16: 平日,祝日 | H16: 社会福祉法人ほのぼの会 | I16: 3250480062 | J16: https://mandanosato.jp/pages/85/
A17: 訪問リハビリテーションほのぼの苑 | B17: 大社 | C17: 出雲市大社町中荒木1745-2 | D17: 0853-53-6700 | E17: 0853-53-6701 | G17: 平日,土曜日,祝日 | H17: 医療法人清風会 | I17: 3270401833 | J17: https://www.sunlight.or.jp/
A18: 医療法人 吉翔会 吉直整形外科クリニック 訪問リハビリテーション「STEP」 | B18: 平田 | C18: 島根県出雲市西平田町242吉直整形外科クリニック吉直整形外科クリニック | D18: 0853-63-2141 | E18: 0853-63-3977 | G18: 平日 | H18: 医療法人吉翔会 | I18: 3210310375 | J18: https://sites.google.com/a/yoshinao-orthopaedic-clinic.com/clinic/

Sheet 通所介護
A1: 通所介護（出雲市・38件）
A2: 事業所名 | B2: エリア | C2: 住所 | D2: 電話番号 | E2: FAX | F2: 定員 | G2: 営業日 | H2: 運営法人 | I2: 事業所番号 | J2: ホームページ | K2: 料金ページ
A3: あすなろ指定通所介護事業所 | B3: 出雲 | C3: 島根県出雲市白枝町395-2 | D3: 0853-23-0078 | E3: 0853-23-8544 | G3: 平日,土曜日,祝日 | H3: 社会福祉法人 あすなろ会 | I3: 3270400371 | J3: https://www.asunaro-izumo.or.jp
A4: 出雲ケアセンター そよ風 | B4: 出雲 | C4: 島根県出雲市今市町876-9 | D4: 0853-20-0950 | E4: 0853-20-0956 | F4: 30 | G4: 平日,土曜日,祝日 | H4: 株式会社ＳＯＹＯＫＡＺＥ | I4: 3270401254 | J4: https://www.sykz.co.jp/
A5: 出雲サンホーム地域福祉サービスセンターソレイユ | B5: 出雲 | C5: 島根県出雲市神西沖町１３１５ | D5: 0853-43-7575 | E5: 0853-43-7577 | G5: 平日,祝日 | H5: 社会福祉法人恵寿会 | I5: 3270403037 | J5: https://www.keijukai.jp/
A6: いなさ園デイサービスセンター | B6: 大社 | C6: 出雲市大社町杵築西１６４３番地２ | D6: 0853-53-5727 | E6: 0853-53-5025 | G6: 平日,祝日 | H6: 社会福祉法人きづき会 | I6: 3271600235 | J6: http://www.kidukikai.or.jp
A7: 株式会社 デイサービス・キートス | B7: 出雲 | C7: 小山町４０４番地４ＹＡＭＡＭＯＴＯビル １ＦＹＡＭＡＭＯＴＯビル １Ｆ | D7: 0853－30－0125 | E7: 0853－25－8082 | F7: 15 | G7: 平日,土曜日,祝日 | H7: 株式会社デイサービス・キートス | I7: 3270402286 | J7: https://kiitos0610.simdif.com/
A8: 社会福祉法人ひらた福祉会 花水木 | B8: 平田 | C8: 島根県出雲市灘分町７８６－１ | D8: 0853-63-7203 | E8: 0853-63-4627 | F8: 2 | G8: 平日,土曜日,祝日 | H8: 社会福祉法人 ひらた福祉会 | I8: 3270401585
A9: 出東デイサービスセンター | B9: 斐川 | C9: 島根県出雲市斐川町三分市1077 | D9: 0853-63-3777 | E9: 0853-63-7007 | G9: 平日,祝日 | H9: 社会福祉法人出東福祉会 | I9: 3271600144 | J9: https://syuttou-fukushikai.net/day/
A10: ＪＡしまねデイサービスセンターつつじ園 | B10: 斐川 | C10: 島根県出雲市斐川町直江885番地 | D10: 0853-73-7314 | E10: 0853-73-7315 | G10: 平日,土曜日,祝日 | H10: 島根県農業協同組合 | I10: 3270402583 | J10: https://ja-shimane.jp/
A11: 清流園通所介護事業所 | B11: 出雲 | C11: 出雲市大津町3529番地 | D11: 0853-21-8333 | E11: 0853-22-8739 | F11: 60 | G11: 平日,土曜日,日曜日,祝日 | H11: 社会福祉法人 静和会 | I11: 3270400082
A12: 第二ことぶき園通所介護事業所 | B12: 出雲 | C12: 出雲市古志町2105－1 | D12: 0853-20-2685 | E12: 0853-20-2688 | F12: 30 | G12: 平日,土曜日,祝日 | H12: 社会福祉法人ことぶき福祉会 | I12: 3270400132 | J12: https://kotobuki1071.jimdofree.com
A13: 通所介護事業所みずほの里 | B13: 平田 | C13: 島根県出雲市灘分町239番地2 | D13: 0853-31-4815 | E13: 0853-63-3670 | G13: 平日,土曜日,祝日 | H13: 株式会社 テーリング | I13: 3270402302 | J13: https://mizuhonoie.com
A14: 通所介護事業所みずほの里 ひやま | B14: 平田 | C14: 島根県出雲市岡田町136番地4 | D14: 0853-25-8477 | E14: 0853-62-3730 | G14: 平日,祝日 | H14: 株式会社テーリング | I14: 3270403227 | J14: https://mizuhonoie.com
A15: 通所介護事業所みずほの里 らいと | B15: 平田 | C15: 島根県出雲市灘分町239番地6 | D15: 0853-31-4833 | E15: 0853-63-3670 | G15: 平日,土曜日,祝日 | H15: 株式会社テーリング | I15: 3270402765 | J15: https://mizuhonoie.com
A16: ツクイ出雲下沢 | B16: 出雲 | C16: 出雲市上塩冶町2655-2 | D16: 0853-20-1120 | E16: 0853-20-1121 | G16: 平日,土曜日,日曜日,祝日 | H16: 株式会社ツクイ | I16: 3270403185
A17: デイサービス サン・スマイル | B17: 出雲 | C17: 島根県出雲市神西沖町215-1 | D17: 0853-43-2170 | E17: 0853-43-2300 | G17: 平日,土曜日,祝日 | H17: 社会福祉法人恵寿会 | I17: 3271600102 | J17: https://www.keijukai.jp/
A18: デイサービス暖談 | B18: 大社 | C18: 島根県出雲市大社町遙堪666番地 | D18: 0853-53-2135 | E18: 0853-53-8240 | F18: 25 | G18: 平日,土曜日,祝日 | H18: 株式会社ピュアライフ島根 | I18: 3271600532
A19: デイサービス ハートキュアひらた | B19: 平田 | C19: 出雲市国富町832-2 | D19: 0853-62-5189 | E19: 0853-62-5605 | F19: 19 | G19: 平日,土曜日,祝日 | H19: 有限会社ハートキュアエム | I19: 3270300209
A20: デイサービス MILK富ロングラフ | B20: 斐川 | C20: 島根県出雲市斐川町富村1465-1 | D20: (0853)31-4450 | E20: (0853)73-8901 | F20: 25 | G20: 平日,土曜日,祝日 | H20: 株式会社Ｃａｒｅ Ｉｎｎｏｖａｔｉｏｎ | I20: 3270402518
A21: デイサービスセンターたき | B21: 多伎 | C21: 出雲市多伎町小田50－8 | D21: 0853-86-2593 | E21: 0853-86-2972 | G21: 平日,土曜日,祝日 | H21: 社会福祉法人多伎の郷 | I21: 3271600250 | J21: https://www.takinosato.jp/
A22: デイサービスセンターるんびにぃ苑 | B22: 平田 | C22: 出雲市園町字妻ノ神2606番地1 | D22: 0853-69-1536 | E22: 0853-67-0457 | F22: 25 | G22: 平日,土曜日,祝日 | H22: 社会福祉法人 真心会 | I22: 3270300183 | J22: https://lumbini-en.jp/
A23: デイサービスMILK富 | B23: 斐川 | C23: 島根県出雲市斐川町富村１４６５－１ | D23: (0853)73-8900 | E23: (0853)73-8901 | F23: 25 | G23: 平日,土曜日,祝日 | H23: 株式会社Ｃａｒｅ Ｉｎｎｏｖａｔｉｏｎ | I23: 3270402492
A24: ナカヤ寿楽 | B24: 出雲 | C24: 島根県出雲市荒茅町3106番地 | D24: 0853-31-9988 | E24: 0853-31-9989 | F24: 25 | G24: 平日,土曜日 | H24: 株式会社 ナカヤ | I24: 3270402906 | J24: https://nakaya-juraku.jp/
A25: なのはな園デイサービスセンター | B25: 斐川 | C25: 斐川町上直江1829-1 | D25: 0853-73-9313 | E25: 0853-72-4030 | F25: 30 | G25: 平日,土曜日,祝日 | H25: 社会福祉法人 島根ライトハウス | I25: 3271600177
A26: ニチイケアセンター出雲 | B26: 出雲 | C26: 出雲市大津朝倉3丁目4-5 | D26: 0853-20-7381 | E26: 0853-20-7380 | F26: 30 | G26: 平日,土曜日,祝日 | H26: 株式会社 ニチイ学館 | I26: 3270402088 | J26: https://www.nichiigakkan.co.jp
A27: 浜山デイサービスセンター野いちご | B27: 大社 | C27: 島根県出雲市大社町北荒木1512-5 | D27: 0853-53-8060 | E27: 0853-53-8061 | G27: 平日,祝日 | H27: 社会福祉法人やまゆり | I27: 3270403458 | J27: http://www.izumo-yamayuri.or.jp
A28: ひかわ生協 デイサービスつむぎ | B28: 斐川 | C28: 島根県出雲市斐川町直江4778番地1 | D28: 0853-31-4760 | E28: 0853-31-4760 | G28: 平日,土曜日,祝日 | H28: ひかわ医療生活協同組合 | I28: 3270403177 | J28: https://www.hikawa-hp.com
A29: ひかわ生協デイサービス きずな | B29: 斐川 | C29: 島根県出雲市斐川町直江4883-1 | D29: 0853-72-0373 | E29: 0853-72-8933 | G29: 平日,土曜日,祝日 | H29: ひかわ医療生活協同組合 | I29: 3270402450 | J29: https://www.hikawa-hp.com
A30: ひまわり園デイサービスセンター | B30: 出雲 | C30: 出雲市神西沖町2513-8 | D30: 0853-43-3528 | E30: 0853-43-2747 | G30: 平日,土曜日,祝日 | H30: 社会福祉法人ひまわり福祉会 | I30: 3270400298 | J30: http://w-himawari.jp
A31: 平田西デイサービスセンター | B31: 平田 | C31: 島根県出雲市国富町57-1 | D31: 0853-63-7337 | E31: 0853-63-7338 | G31: 平日,祝日 | H31: 社会福祉法人 おおつか福祉会 | I31: 3270401072 | J31: https://www.otuka-wel.jp
A32: 平田ほのぼの通所介護事業所 | B32: 平田 | C32: 出雲市平田町7169 | D32: 0853-25-7169 | E32: 0853-62-3369 | G32: 平日,土曜日,祝日 | H32: 社会福祉法人ほのぼの会 | I32: 3270300068 | J32: https://mandanosato.jp/
A33: 穂なみデイサービスセンター | B33: 出雲 | C33: 島根県出雲市里方町１１６番地 | D33: ０８５３－２０－１０２０ | E33: ０８５３－２０－１０２１ | G33: 平日,土曜日,祝日 | H33: 特定非営利活動法人コミュニティサポートいずも | I33: 3270402427
A34: ポラリスデイサービスセンター出雲 | B34: 出雲 | C34: 島根県出雲市今市町1323 | D34: 0853-27-9505 | E34: 0853-27-9507 | G34: 平日,祝日 | H34: 株式会社ポラリス | I34: 3270403243 | J34: https://www.polaris.care/
A35: みせんの里デイサービスセンター | B35: 大社 | C35: 出雲市大社町遙堪65番地2 | D35: 0853-53-2707 | E35: 0853-53-2755 | F35: 25 | G35: 平日,祝日 | H35: 社会福祉法人きづき会 | I35: 3270400942 | J35: http://www.kidukikai.or.jp
A36: みどりの郷出雲 | B36: 出雲 | C36: 出雲市所原町2715-1 | D36: 0853-48-2300 | E36: 0853-48-2301 | G36: 平日,土曜日,日曜日,祝日 | H36: 社会福祉法人ＪＡいずも福祉会 | I36: 3270400157
A37: みどりの郷湖陵 | B37: 湖陵 | C37: 出雲市湖陵町三部1231-1 | D37: 0853-43-3228 | E37: 0853-43-3933 | G37: 平日,土曜日,日曜日,祝日 | H37: 社会福祉法人 ＪＡいずも福祉会 | I37: 3271600045
A38: みどりの郷大社 | B38: 大社 | C38: 出雲市大社町北荒木483 | D38: 0853-53-1333 | E38: 0853-53-6133 | G38: 平日,土曜日,日曜日,祝日 | H38: 社会福祉法人ジェイエイいずも福祉会 | I38: 3270401049 | J38: https://jaizumo-fukushikai.jp
A39: みどりの郷平田 | B39: 平田 | C39: 出雲市平田町２３０８番地９ | D39: 0853-62-9060 | E39: 0853-62-9070 | G39: 平日,土曜日,日曜日,祝日 | H39: 社会福祉法人ＪＡいずも福祉会 | I39: 3270300175 | J39: https://jaizumo-fukushikai.jp/
A40: もくもく苑通所介護事業所 | B40: 出雲 | C40: 出雲市矢野町845 | D40: 0853-21-6969 | E40: 0853-24-3322 | G40: 平日,祝日 | H40: 社会福祉法人 おおつか福祉会 | I40: 3270400413 | J40: https://www.otuka-wel.jp

Sheet 通所リハビリテーション
A1: 通所リハビリテーション（出雲市・12件）
A2: 事業所名 | B2: エリア | C2: 住所 | D2: 電話番号 | E2: FAX | F2: 定員 | G2: 営業日 | H2: 運営法人 | I2: 事業所番号 | J2: ホームページ | K2: 料金ページ
A3: 医療法人社団林整形外科医院 | B3: 出雲 | C3: 姫原町114－3 | D3: 0853-21-1758 | E3: 0853-21-0811 | G3: 平日 | H3: 医療法人社団林整形外科医院 | I3: 3210411223 | J3: http://hayashiseikei.c.ooco.jp/
A4: えだくり通所リハビリテーション | B4: 出雲 | C4: 島根県出雲市今市町藤ヶ森2074 | D4: 0853-31-5515 | E4: 0853-31-5516 | G4: 平日 | H4: 医療法人江田クリニック | I4: 3210412759 | J4: https://izumo.edaclinic.jp/
A5: 大曲診療所 | B5: 出雲 | C5: 出雲市大津町1941 | D5: 0853-21-1731 | E5: 0853-21-1217 | G5: 平日 | H5: 出雲医療生活協同組合 | I5: 3210412106 | J5: https://www.oomagari.com/
A6: 介護老人保健施設ケアセンターかんど | B6: 出雲 | C6: 島根県出雲市西新町２丁目２４５７番地３ | D6: 0853-24-8041 | E6: 0853-24-8114 | G6: 平日,土曜日 | H6: 医療法人かんど会 | I6: 3250480054 | J6: http://www.kandokai.jp/
A7: 介護老人保健施設ほのぼの苑 | B7: 大社 | C7: 出雲市大社町中荒木1745-2 | D7: 0853-53-6700 | E7: 0853-53-6701 | G7: 平日,土曜日,祝日 | H7: 医療法人清風会 | I7: 3251680009 | J7: https://www.sunlight.or.jp
A8: 介護老人保健施設もくもく | B8: 出雲 | C8: 出雲市江田町278番地 | D8: 0853-24-6001 | E8: 0853-24-6621 | G8: 平日,祝日 | H8: 社会福祉法人 おおつか福祉会 | I8: 3250480047 | J8: https://www.otuka-wel.jp/
A9: 寿生苑通所リハビリテーション | B9: 出雲 | C9: 出雲市上塩冶町2862-1 | D9: 0853-25-0088 | E9: 0853-25-0240 | G9: 平日 | H9: 壽生会 | I9: 3250480021 | J9: http://juseikai.jp/
A10: 高鳥クリニック 地域リハビリテーションセンター | B10: 出雲 | C10: 島根県出雲市武志町734-1 | D10: 0853-20-1338 | E10: 0853-24-8515 | F10: 15 | G10: 平日,土曜日 | H10: 医療法人社団岡倉会 | I10: 3210411827
A11: 通所リハビリテーション事業所まんだ | B11: 平田 | C11: 島根県出雲市万田町535番地１ | D11: 0853-63-5610 | E11: 0853-63-5612 | F11: 25 | G11: 平日,土曜日 | H11: 社会福祉法人ほのぼの会 | I11: 3250480062 | J11: https://mandanosato.jp/pages/85/
A12: 深田医院 | B12: 出雲 | C12: 出雲市高岡町５３－１ | D12: 0853-22-8824 | E12: 0853-22-9030 | G12: 平日,土曜日 | H12: 医療法人深田医院 | I12: 3210411983
A13: 医療法人 吉翔会 吉直整形外科クリニック デイケア 「リハホーム」 | B13: 平田 | C13: 島根県出雲市西平田町242吉直整形外科クリニック吉直整形外科クリニック | D13: 0853-63-2141 | E13: 0853-63-3977 | F13: 6 | G13: 平日 | H13: 医療法人吉翔会 | I13: 3210310375 | J13: https://sites.google.com/a/yoshinao-orthopaedic-clinic.com/clinic/
A14: 老人保健施設たき(通所リハビリテーション） | B14: 多伎 | C14: 出雲市多伎町小田50番地7 | D14: 0853-86-2977 | E14: 0853-86-2978 | G14: 平日 | H14: 社会福祉法人多伎の郷 | I14: 3251680018 | J14: https://www.takinosato.jp/

Sheet 福祉用具貸与
A1: 福祉用具貸与（出雲市・19件）
A2: 事業所名 | B2: エリア | C2: 住所 | D2: 電話番号 | E2: FAX | F2: 定員 | G2: 営業日 | H2: 運営法人 | I2: 事業所番号 | J2: ホームページ | K2: 料金ページ
A3: あえる介護ショップ | B3: 出雲 | C3: 出雲市西園町273-1ライフサポートモール蒔庵ライフサポートモール蒔庵 | D3: 0853-25-8921 | E3: 0853-25-8782 | G3: 平日 | H3: 株式会社ソーシャルプランニングネットワーク | I3: 3270400884 | J3: https://www.spn-web.jp/
A4: 出雲レンタル | B4: 出雲 | C4: 島根県出雲市天神町883-1三光ビル4号室三光ビル4号室 | D4: 0853-21-8001 | E4: 0853-21-8002 | G4: 平日 | H4: 株式会社神戸レンタル | I4: 3270403292
A5: 株式会社 歩夢 ケアショップ ももたろう | B5: 斐川 | C5: 島根県出雲市斐川町直江4641-2 | D5: 0853-73-7130 | E5: 0853-73-7150 | G5: 平日 | H5: 株式会社歩夢 | I5: 3271600706
A6: (株)岩多屋福祉事業部出雲 | B6: 出雲 | C6: 島根県出雲市長浜町６５９－２１ | D6: 0853-27-0322 | E6: 0853-27-0320 | G6: 平日,祝日 | H6: 株式会社岩多屋 | I6: 3270402989 | J6: https://www.iwataya-net.co.jp/
A7: 株式会社 こころ | B7: 斐川 | C7: 出雲市斐川町荘原3951 | D7: 0853-25-7564 | E7: 0853-25-7563 | G7: 平日,土曜日 | H7: 株式会社こころ | I7: 3271600672
A8: 株式会社 フルケア 山陰営業所 | B8: 出雲 | C8: 出雲市知井宮町１８５ | D8: 0853-20-1302 | E8: 0853-20-1303 | G8: 平日,土曜日 | H8: 株式会社フルケア | I8: 3270400819 | J8: https://www.full-care.jp/
A9: 株式会社イトガ | B9: 出雲 | C9: 島根県出雲市神西沖町１６８７－１１ | D9: 0853-43-1218 | E9: 0853-43-3450 | G9: 平日 | H9: 株式会社イトガ | I9: 3270401478
A10: 株式会社原商 出雲事業所 | B10: 出雲 | C10: 島根県出雲市長浜町659－39 | D10: 0853-28-3277 | E10: 0853-28-3288 | G10: 平日 | H10: 株式会社原商 | I10: 3270401627 | J10: https://www.harasho.co.jp/company/office/smile-care-office/smile-izumo
A11: 株式会社ホームケアー島根 | B11: 斐川 | C11: 出雲市斐川町上直江2139-135 | D11: 0853-31-7878 | E11: 0853-72-0065 | G11: 平日,土曜日 | H11: 株式会社ホームケアー島根 | I11: 3270400017 | J11: http://www.homecare-shimane.jp/
A12: コニファー 株式会社 | B12: 出雲 | C12: 塩冶神前6－1－8 | D12: 0853－30－0528 | E12: 0853－30－0538 | G12: 平日,土曜日 | H12: コニファー 株式会社 | I12: 3270401544
A13: ジョイ・ケア たいよう | B13: 出雲 | C13: 出雲市荻杼町526-10 | D13: 0853-20-0670 | E13: 0853-20-0671 | G13: 平日,土曜日 | H13: 有限会社 Joy・ケア | I13: 3270400785 | J13: http://www.joycare.jp
A14: ダスキンヘルスレント島根東ステーション | B14: 出雲 | C14: 小山町333-1 | D14: 0853-25-7689 | E14: 0853-24-3164 | G14: 平日 | H14: 株式会社マサコーポレーション | I14: 3270402864 | J14: https://healthrent.duskin.jp/
A15: ハピネライフ一光 出雲支社 | B15: 出雲 | C15: 出雲市渡橋町418番地 | D15: 0853-23-6279 | E15: 0853-23-2267 | G15: 平日 | H15: 株式会社ハピネライフ一光 | I15: 3270400231 | J15: https://www.hapine.com/
A16: まるてい介護福祉事業所 | B16: 出雲 | C16: 出雲市白枝町４２７－４ | D16: 0853-20-1570 | E16: 0853-20-1571 | G16: 平日,土曜日 | H16: 有限会社エム・アール・シー | I16: 3270400587
A17: 有限会社出雲リハビリサービス | B17: 出雲 | C17: 島根県出雲市今市町547 | D17: 0853-22-3963 | E17: 0853-23-7578 | G17: 平日,土曜日 | H17: 有限会社出雲リハビリサービス | I17: 3270400702
A18: 有限会社 介護ショップもちだ | B18: 出雲 | C18: 出雲市矢尾町885-1 | D18: 0853-25-2016 | E18: 0853-25-2028 | G18: 平日 | H18: 有限会社 介護ショップもちだ | I18: 3270400389
A19: 有限会社 げんき堂 出雲営業所 | B19: 出雲 | C19: 知井宮町185番地 | D19: 0853-20-1302 | E19: 0853-20-1303 | G19: 平日 | H19: 有限会社げんき堂 | I19: 3270403433 | J19: https://genkido-info.jimdofree.com/
A20: 有限会社アイライフ | B20: 出雲 | C20: 出雲市里方町893-5 | D20: 0853-23-6389 | E20: 0853-23-6325 | G20: 平日,土曜日 | H20: 有限会社アイライフ | I20: 3270400470
A21: ゆず | B21: 斐川 | C21: 島根県出雲市斐川町神氷2871 | D21: 0853-72-7209 | E21: 0853-72-7289 | G21: 平日 | H21: 株式会社 ゆず | I21: 3270402823 | J21: https://yuzu-izumo.com/

Sheet 短期入所生活介護
A1: 短期入所生活介護（出雲市・23件）
A2: 事業所名 | B2: エリア | C2: 住所 | D2: 電話番号 | E2: FAX | F2: 定員 | G2: 営業日 | H2: 運営法人 | I2: 事業所番号 | J2: ホームページ | K2: 料金ページ
A3: 出雲ケアセンターそよ風 | B3: 出雲 | C3: 島根県出雲市今市町８７６－９ | D3: 0853-20-0950 | E3: 0853-20-0956 | F3: 20 | H3: 株式会社ＳＯＹＯＫＡＺＥ | I3: 3270401254 | J3: https://www.sykz.co.jp/
A4: 出雲サンホーム短期入所事業所 | B4: 出雲 | C4: 島根県出雲市神西沖町１３１３ | D4: 0853-43-3200 | E4: 0853-43-2030 | H4: 社会福祉法人恵寿会 | I4: 3270403086 | J4: https://www.keijukai.jp/
A5: 出雲市里方町795番地 | B5: 出雲 | C5: 里方町795番地あかりの里高浜あかりの里高浜 | D5: 0853-20-1322 | E5: 0853-20-1323 | H5: 株式会社ラッシュ | I5: 3270403045 | J5: https://lush-care.jp/
A6: ショートステイ サン・スマイル | B6: 出雲 | C6: 島根県出雲市神西沖町215-1 | D6: 0853-43-3600 | E6: 0853-43-2300 | H6: 社会福祉法人恵寿会 | I6: 3271600110 | J6: https://www.keijukai.jp/
A7: 清流園 地域密着型短期入所生活介護事業所 | B7: 出雲 | C7: 島根県出雲市大津町3529番地 | D7: 0853-22-8706 | E7: 0853-22-7267 | H7: 社会福祉法人 静和会 | I7: 3270402963 | J7: https://www.seiryuuen.com/
A8: 清流園短期入所生活介護事業所 | B8: 出雲 | C8: 出雲市大津町3529番地 | D8: 0853-22-8706 | E8: 0853-22-7267 | H8: 社会福祉法人 静和会 | I8: 3270400173 | J8: https://www.seiryuuen.com/
A9: 短期入所生活介護事業所 かんべの里 | B9: 斐川 | C9: 島根県出雲市斐川町名島93番地2 | D9: 0853-72-3097 | E9: 0853-72-3190 | F9: 10 | H9: 社会福祉法人 喜和会 | I9: 3271690079 | J9: https://taiyounosato.or.jp/
A10: 特別養護老人ホーム薫風園 | B10: 出雲 | C10: 島根県大津町3620番地１ | D10: 0853‐31‐9155 | E10: 0853‐31‐9166 | H10: 社会福祉法人いずも南福祉会 | I10: 3270402880 | J10: https://www.izumo-minami.jp/business/kunpuen | K10: https://www.izumo-minami.jp/files/guidance_plugin/guidance_20250404062326.pdf
A11: 特別養護老人ホーム いなさ園 短期入所生活介護事業所 | B11: 大社 | C11: 島根県出雲市大社町杵築西１６４３番地２ | D11: 0853-53-5727 | E11: 0853-53-5025 | F11: 10 | H11: 社会福祉法人きづき会 | I11: 3271690038 | J11: http://www.kidukikai.or.jp
A12: 特別養護老人ホーム サテライトおやま | B12: 出雲 | C12: 島根県出雲市小山町456-1 | D12: 0853-23-6149 | E12: 0853-22-8749 | H12: 島根県社会福祉事業団 | I12: 3270402633 | J12: https://www.ssw.or.jp
A13: 特別養護老人ホーム なのはな園 | B13: 斐川 | C13: 出雲市斐川町上直江1829-1 | D13: 0853-72-1101 | E13: 0853-72-4030 | F13: 14 | H13: 社会福祉法人島根ライトハウス | I13: 3271690046 | J13: http://s-lighthouse.jp/
A14: 特別養護老人ホーム潮風苑 | B14: 多伎 | C14: 島根県出雲市多伎町小田50－3 | D14: 0853-86-2030 | E14: 0853-86-2972 | H14: 社会福祉法人多伎の郷 | I14: 3271690020
A15: 特別養護老人ホーム天神 | B15: 出雲 | C15: 出雲市天神町163-9 | D15: 0853-22-8659 | E15: 0853-25-0750 | H15: 島根県社会福祉事業団 | I15: 3270490018 | J15: https://www.ssw.or.jp/facilities/seniors/tenjin
A16: 特別養護老人ホームひまわり園 | B16: 出雲 | C16: 出雲市神西沖町2513-4 | D16: 0853-43-2633 | E16: 0853-43-2747 | F16: 10 | H16: 社会福祉法人ひまわり福祉会 | I16: 3270490026 | J16: http://w-himawari.jp
A17: 特別養護老人ホームみせんの里 | B17: 大社 | C17: 出雲市大社町遙堪65番地2 | D17: 0853-53-2007 | E17: 0853-53-2755 | H17: 社会福祉法人きづき会 | I17: 3270490059 | J17: http://www.kidukikai.or.jp
A18: 特別養護老人ホームるんびにぃ苑指定短期入所生活介護事業所 | B18: 平田 | C18: 出雲市園町字妻ノ神2606番地1 | D18: 0853-69-1211 | E18: 0853-67-0457 | F18: 10 | H18: 社会福祉法人真心会 | I18: 3270300100 | J18: https://lumbini-en.jp/
A19: 万田の郷短期入所生活介護事業所 | B19: 平田 | C19: 出雲市万田町692-2 | D19: 0853-63-2650 | E19: 0853-63-2665 | H19: 社会福祉法人ほのぼの会 | I19: 3270300076 | J19: https://mandanosato.jp/ | K19: https://mandanosato.jp/pages/84/
A20: 万田の郷（新型）短期入所生活介護事業所 | B20: 平田 | C20: 島根県出雲市万田町538 | D20: 0853-63-2855 | E20: 0853-31-4801 | H20: 社会福祉法人ほのぼの会 | I20: 3270402484 | J20: https://mandanosato.jp/ | K20: https://mandanosato.jp/pages/84/
A21: みどりの郷出雲 | B21: 出雲 | C21: 島根県出雲市所原町２７１５－１ | D21: 0853-48-9023 | E21: 0853-48-2301 | H21: 社会福祉法人ＪＡいずも福祉会 | I21: 3270400157
A22: みどりの郷湖陵 | B22: 湖陵 | C22: 出雲市湖陵町三部1231-1 | D22: 0853-43-3934 | E22: 0853-43-3933 | H22: 社会福祉法人 ＪＡいずも福祉会 | I22: 3271600045
A23: もくもく苑短期入所生活介護事業所 | B23: 出雲 | C23: 島根県出雲市矢野町845 | D23: 0853-21-6969 | E23: 0853-24-3322 | H23: 社会福祉法人 おおつか福祉会 | I23: 3270400421 | J23: https://www.otuka-wel.jp
A24: やまゆり短期入所事業所 | B24: 佐田 | C24: 島根県出雲市佐田町一窪田1961-5 | D24: 0853-85-8000 | E24: 0853-85-8010 | H24: 社会福祉法人やまゆり | I24: 3270401353 | J24: http://www.izumo-yamayuri.or.jp/tannki.html
A25: ユニット型特別養護老人ホームなのはな園 | B25: 斐川 | C25: 島根県出雲市斐川町上直江1829－１ | D25: 0853-72-7222 | E25: 0853-72-4030 | H25: 島根ライトハウス | I25: 3270490083 | J25: http://www.s-lighthouse.jp

Sheet 短期入所療養(老健)
A1: 短期入所療養介護（介護老人保健施設）（出雲市・8件）
A2: 事業所名 | B2: エリア | C2: 住所 | D2: 電話番号 | E2: FAX | F2: 定員 | G2: 営業日 | H2: 運営法人 | I2: 事業所番号 | J2: ホームページ | K2: 料金ページ
A3: 介護老人保健施設ケアセンターかんど | B3: 出雲 | C3: 島根県出雲市西新町２丁目２４５７番地３ | D3: 0853-24-8041 | E3: 0853-24-8114 | H3: 医療法人かんど会 | I3: 3250480054 | J3: http://www.kandokai.jp/
A4: 介護老人保健施設 寿生苑 | B4: 出雲 | C4: 出雲市上塩冶町2862-1 | D4: 0853-25-0088 | E4: 0853-25-0240 | H4: 壽生会 | I4: 3250480021 | J4: http://juseikai.jp/
A5: 介護老人保健施設ほのぼの苑 | B5: 大社 | C5: 出雲市大社町中荒木1745-2 | D5: 0853-53-6700 | E5: 0853-53-6701 | H5: 医療法人清風会 | I5: 3251680009 | J5: https://www.sunlight.or.jp
A6: 介護老人保健施設もくもく | B6: 出雲 | C6: 出雲市江田町278番地 | D6: 0853-24-6001 | E6: 0853-24-6621 | H6: 社会福祉法人 おおつか福祉会 | I6: 3250480047 | J6: https://www.otuka-wel.jp/
A7: 介護老人保健施設 出雲徳洲苑 | B7: 斐川 | C7: 島根県出雲市斐川町直江3964-1 | D7: 0853-73-7577 | E7: 0853-73-7570 | F7: 3 | H7: 医療法人徳洲会 | I7: 3250480088 | J7: https://izumo-tokushuen.com/ | K7: https://izumo-tokushuen.com/price
A8: 短期入所療養介護事業所まんだ | B8: 平田 | C8: 島根県出雲市万田町５３５－１ | D8: 0853-63-5610 | E8: 0853-63-5612 | H8: 社会福祉法人 ほのぼの会 | I8: 3250480062 | J8: https://mandanosato.jp/pages/85/ | K8: https://mandanosato.jp/pages/84/
A9: ナーシングセンターひまわり | B9: 出雲 | C9: 出雲市古志町2236-1 | D9: 0853-21-7954 | E9: 0853-21-7957 | H9: 社会福祉法人ひまわり福祉会 | I9: 3250480013 | J9: http://w-himawari.or.jp/
A10: 老人保健施設たき | B10: 多伎 | C10: 島根県出雲市多伎町小田50番地7 | D10: 0853-86-2977 | E10: 0853-86-2978 | F10: 5 | H10: 社会福祉法人多伎の郷 | I10: 3251680018 | J10: https://www.takinosato.jp/

Sheet グループホーム
A1: 認知症対応型共同生活介護（出雲市・37件）
A2: 事業所名 | B2: エリア | C2: 住所 | D2: 電話番号 | E2: FAX | F2: 定員 | G2: 営業日 | H2: 運営法人 | I2: 事業所番号 | J2: ホームページ | K2: 料金ページ
A3: あかねの里認知症対応型共同生活介護事業所 | B3: 平田 | C3: 島根県出雲市平田町7169 | D3: 0853-62-3133 | E3: 0853-62-3369 | H3: 社会福祉法人 ほのぼの会 | I3: 3270300092 | J3: https://mandanosato.jp/
A4: 出雲ケアセンターそよ風 | B4: 出雲 | C4: 出雲市今市町876－9 | D4: 0853-20-0950 | E4: 0853-20-0956 | F4: 18 | H4: 株式会社ＳＯＹＯＫＡＺＥ | I4: 3290400138
A5: 株式会社 リ・コネクト グループホーム北陽 | B5: 出雲 | C5: 島根県出雲市武志町755-2 | D5: 0853-25-8000 | E5: 0853-25-8001 | F5: 18 | I5: 3290400393
A6: グループホーム くらすところ御はつ | B6: 出雲 | C6: 島根県出雲市下古志町751番地6 | D6: 0853-24-0082 | E6: 0853-24-0081 | H6: 株式会社おはつ | I6: 3290400682 | J6: https://ohatsu.jp/ | K6: https://ohatsu.jp/kurashi-about/kurashi-price/
A7: グループホーム 寿生の丘 | B7: 出雲 | C7: 島根県出雲市大津町３６２２－１５ | D7: 0853-30-6212 | E7: 0853-23-2563 | F7: 18 | H7: 社会福祉法人出雲南福祉会 | I7: 3270400595 | J7: https://www.izumo-minami.jp
A8: グループホーム せせらぎの家 | B8: 佐田 | C8: 出雲市佐田町一窪田118番地19 | D8: 0853-85-8500 | E8: 0853-85-8501 | H8: 社会福祉法人 やまゆり | I8: 3290400187 | J8: http://www.izumo-yamayuri.or.jp
A9: グループホーム 暖らん | B9: 出雲 | C9: 島根県出雲市塩冶町南町1-1-37 | D9: 0853-25-8581 | E9: 0853-25-8582 | F9: 9 | H9: 星隆会 | I9: 3290400609 | J9: https://www.kiichigo-danran.jp/danran
A10: グループホーム ハートキュアひらた | B10: 平田 | C10: 出雲市国富町832-2 | D10: 0853-62-5166 | E10: 0853-62-5605 | F10: 18 | H10: 有限会社ハートキュアエム | I10: 3270300191
A11: グループホーム萌 | B11: 斐川 | C11: 島根県出雲市斐川町学頭１３２２－１ | D11: 0853-73-7170 | E11: 0853-73-7177 | F11: 18 | H11: 有限会社美奈須 | I11: 3271600458 | J11: https://gh-moe.com/
A12: グループホームやまもも | B12: 平田 | C12: 島根県出雲市美野町504 | D12: 0853-67-9180 | E12: 0853-67-9181 | H12: 有限会社 伊野本陣 | I12: 3290400088 | J12: http://inohonjin.jp/
A13: グループホーム縁 | B13: 大社 | C13: 島根県出雲市大社町遙堪666 | D13: 0853-25-8720 | E13: 0853-53-2355 | F13: 9 | H13: 株式会社ピュアライフ島根 | I13: 3290400617
A14: グループホーム風の丘 | B14: 平田 | C14: 小津町23-1 | D14: 0853-66-0233 | E14: 0853-66-0236 | F14: 18 | H14: みなとの丘グループ株式会社 | I14: 3290400427
A15: グループホームきづきの家 | B15: 大社 | C15: 大社町杵築西２６２９ | D15: ０８５３－５３－２３２２ | E15: ０８５３－５３－２３８０ | H15: 社会福祉法人きづき会 | I15: 3290400401 | J15: http://www.kidukikai.or.jp
A16: グループホーム湖水苑 | B16: 湖陵 | C16: 島根県出雲市湖陵町差海318-1 | D16: 0853-43-0032 | E16: 0853-43-0995 | F16: 27 | H16: 社会福祉法人壽光会 | I16: 3290400690 | J16: https://jukokai.jp/
A17: グループホームさくらんぼ | B17: 斐川 | C17: 島根県出雲市斐川町今在家４０３番地１ | D17: 0853-73-7410 | E17: 0853-73-7412 | H17: 有限会社三幸 | I17: 3271600607
A18: グループホームさらさの家 | B18: 平田 | C18: 出雲市東福町190－2 | D18: 0853-63-7707 | E18: 0853-63-7717 | F18: 9 | H18: 株式会社建装 | I18: 3290400294
A19: グループホームしあわせの里 | B19: 平田 | C19: 島根県出雲市上岡田町1031-1 | D19: 0853-31-4824 | E19: 0853-31-4429 | H19: 社会福祉法人ほのぼの会 | I19: 3290400419 | J19: https://mandanosato.jp/
A20: グループホーム四季彩 | B20: 平田 | C20: 島根県出雲市灘分町２０４－２ | D20: 0853-62-1431 | E20: 0853-62-1433 | H20: 有限会社 佐香 | I20: 3270300167
A21: グループホーム出東ララ | B21: 斐川 | C21: 島根県出雲市斐川町三分市1072番地1 | D21: 0853-25-8020 | E21: 0853-25-8021 | F21: 18 | H21: 社会福祉法人出東福祉会 | I21: 3290400385 | J21: http://syuttou-fukushikai.net/rara/pg21.html
A22: グループホーム寿生の家 | B22: 出雲 | C22: 出雲市上塩冶町2854-3 | D22: 0853-30-1110 | E22: 0853-25-0285 | F22: 18 | H22: 壽生会 | I22: 3270400314 | J22: http://www.juseikai.jp/
A23: グループホーム大社 | B23: 大社 | C23: 島根県出雲市大社町中荒木２６１７－８５ | D23: 0853-53-2545 | E23: 0853-53-0781 | F23: 18 | H23: 社会福祉法人縁むすび福祉会 | I23: 3290400476 | J23: https://www.shinjirakuen.jp/
A24: グループホームたくひの里 | B24: 出雲 | C24: 島根県出雲市大津町3645 | D24: 0853-20-1770 | E24: 0853-20-1772 | F24: 18 | H24: Ｕｐ ｗｅｌｌ | I24: 3270400900
A25: グループホーム暖談 | B25: 大社 | C25: 島根県出雲市大社町遙堪666 | D25: 0853-53-5303 | E25: 0853-53-2923 | H25: 株式会社ピュアライフ島根 | I25: 3271600524
A26: グループホーム なかだ浜山の里 | B26: 出雲 | C26: 島根県出雲市浜町５００－１ | D26: 0853-23-8588 | E26: 0853-23-8577 | F26: 18 | H26: 有限会社 なかだ | I26: 3290400179
A27: グループホームはなんばの里 | B27: 多伎 | C27: 島根県出雲市多伎町口田儀750番地 | D27: 0853-86-7700 | E27: 0853-86-3577 | H27: 社会福祉法人多伎の郷 | I27: 3290400112
A28: グループホーム稗原 | B28: 出雲 | C28: 島根県出雲市稗原町1724グループホーム稗原グループホーム稗原 | D28: 0853-48-9045 | E28: 0853-48-9008 | F28: 18 | H28: 株式会社さくら | I28: 3290400146
A29: グループホーム水の元 | B29: 出雲 | C29: 島根県出雲市東園町529番地1 | D29: 0853-25-8330 | E29: 0853-25-8440 | F29: 18 | H29: 株式会社結水織 | I29: 3290400666
A30: グループホームもくれん | B30: 湖陵 | C30: 島根県出雲市湖陵町三部964-1 | D30: 0853-43-8522 | E30: 0853-43-8533 | F30: 18 | H30: 株式会社もくれん | I30: 3290400450 | J30: https://www.izumo-mokuren.com/ | K30: https://www.izumo-mokuren.com/price/
A31: グループホーム柳緑の里 | B31: 斐川 | C31: 島根県出雲市斐川町学頭1815-6グループホーム柳緑の里グループホーム柳緑の里 | D31: 0853-31-9530 | E31: 0853-72-3200 | H31: 株式会社ラッシュ | I31: 3290400641 | J31: https://lush-care.jp/
A32: けあビジョンホーム出雲 | B32: 斐川 | C32: 斐川町荘原2320-1 | D32: 0853-73-7111 | E32: 0853-73-7110 | F32: 18 | H32: 株式会社ビジュアルビジョン | I32: 3290400633
A33: サンキ・ウエルビィ グループホーム出雲 | B33: 大社 | C33: 島根県出雲市大社町北荒木１３１３-2 | D33: 0853-53-8070 | E33: 0853-53-8071 | F33: 18 | H33: サンキ・ウエルビィ株式会社 | I33: 3290400245
A34: 認知症高齢者グループホーム 宇賀の杜 楽舎 | B34: 平田 | C34: 出雲市奥宇賀町23番地1 | D34: 0853-63-7373 | E34: 0853-63-7370 | F34: 18 | H34: 有限会社楽舎 | I34: 3270400967 | J34: http://www.rakuya-izumo.jp | K34: http://www.rakuya-izumo.jp/price/index.html
A35: 認知症高齢者グループホーム宇賀の里楽舎 | B35: 平田 | C35: 出雲市奥宇賀町23番地10 | D35: 0853-31-9885 | E35: 0853-63-7371 | H35: 有限会社 楽舎 | I35: 3290400153 | J35: http://www.rakuya-izumo.jp | K35: http://www.rakuya-izumo.jp/price/index.html
A36: 認知症対応型共同生活介護グループホームかんどの里 | B36: 出雲 | C36: 島根県出雲市神門町13番地5 | D36: 0853-20-1150 | E36: 0853-20-1153 | F36: 9 | H36: 社会福祉法人神門福祉会 | I36: 3290400161 | J36: https://kando-h.sakura.ne.jp/
A37: 認知症対応型グループホームすいせん渡橋 | B37: 出雲 | C37: 出雲市渡橋町３０４番地１ハピネケアセンター出雲ハピネケアセンター出雲 | D37: 0853-23-8810 | E37: 0853-23-6678 | H37: 株式会社ハピネライフ一光 | I37: 3290400211 | J37: https://www.hapine.com/
A38: ハートフルおやま | B38: 出雲 | C38: 出雲市小山町456-1 | D38: 0853-30-7553 | E38: 0853-30-7553 | H38: 島根県社会福祉事業団 | I38: 3270400694 | J38: https://www.ssw.or.jp/facilities/seniors/tenjin/394
A39: ひだまり | B39: 出雲 | C39: 出雲市神西沖町2452-1 | D39: 0853-43-3755 | E39: 0853-43-3756 | F39: 18 | H39: 社会福祉法人ひまわり福祉会 | I39: 3270400710 | J39: https://www.w-himawari.jp/kaigo/tokuyou-honkan/

Sheet 特定施設(有料老人ホーム)
A1: 特定施設入居者生活介護（有料老人ホーム）（出雲市・6件）
A2: 事業所名 | B2: エリア | C2: 住所 | D2: 電話番号 | E2: FAX | F2: 定員 | G2: 営業日 | H2: 運営法人 | I2: 事業所番号 | J2: ホームページ | K2: 料金ページ
A3: 出雲鳳光苑 | B3: 出雲 | C3: 島根県出雲市塩冶町879番地 | D3: 0853-20-1411 | E3: 0853-20-1410 | F3: 30 | H3: 株式会社ハピネライフ一光 | I3: 3270401239 | J3: http://www.h-ikkou.co.jp
A4: ハーモニーハウス出雲 | B4: 出雲 | C4: 出雲市塩冶町1174-3 | D4: 0853-20-0099 | E4: 0853-22-2290 | H4: 株式会社ハピネライフ一光 | I4: 3270401692 | J4: http://www.h-ikkou.co.jp/index.php
A5: 鳳光苑 | B5: 斐川 | C5: 島根県出雲市斐川町上庄原1634番地5 | D5: 0853-73-7368 | E5: 0853-73-7367 | H5: 株式会社ハピネライフ一光 | I5: 3271600649 | J5: http://www.h-ikkou.co.jp/index.php
A6: ホーム・スイートホーム きらり | B6: 湖陵 | C6: 島根県出雲市湖陵町二部1192番1 | D6: 0853-43-7005 | E6: 0853-43-7006 | F6: 50 | H6: 株式会社中林建築設計事務所 | I6: 3270401270 | J6: http://www.h-sweet-home.com
A7: ゆうらいふ長浜 | B7: 出雲 | C7: 出雲市荒茅町3501番地 | D7: 0853-28-0345 | E7: 0853-28-0339 | F7: 50 | H7: 株式会社ライフサポート | I7: 3270401312 | J7: http://www.youlife-n.com
A8: 有料老人ホームいこいの郷 | B8: 出雲 | C8: 出雲市西林木町33番地1 | D8: 0853-21-6363 | E8: 0853-21-6353 | F8: 42 | H8: シルバーコミュニティセンター株式会社 | I8: 3270400264 | J8: https://www.izumo-net.ne.jp/~ikoi/ | K8: https://www.izumo-net.ne.jp/~ikoi/riyouryoukinn.htm

Sheet 特定施設(軽費老人ホーム)
A1: 特定施設入居者生活介護（軽費老人ホーム）（出雲市・2件）
A2: 事業所名 | B2: エリア | C2: 住所 | D2: 電話番号 | E2: FAX | F2: 定員 | G2: 営業日 | H2: 運営法人 | I2: 事業所番号 | J2: ホームページ | K2: 料金ページ
A3: ケアハウス ふるさと苑 | B3: 大社 | C3: 出雲市大社町中荒木1745-2 | D3: 0853-53-6705 | E3: 0853-53-6701 | F3: 50 | H3: 社会福祉法人まほろばの郷 | I3: 3271600359 | J3: https://www.sunlight.or.jp
A4: ケアハウスあすなろ | B4: 出雲 | C4: 島根県出雲市白枝町396-2 | D4: 0853-22-4801 | E4: 0853-25-1158 | H4: 社会福祉法人 あすなろ会 | I4: 3270402229 | J4: https://www.asunaro-izumo.or.jp/carehouse/

Sheet 特定施設入居者生活介護(有料老人ホーム(サービス付き高齢者向け
A1: 特定施設入居者生活介護（有料老人ホーム（サービス付き高齢者向け住宅））（出雲市・2件）
A2: 事業所名 | B2: エリア | C2: 住所 | D2: 電話番号 | E2: FAX | F2: 定員 | G2: 営業日 | H2: 運営法人 | I2: 事業所番号 | J2: ホームページ | K2: 料金ページ
A3: シニアコート平田町 | B3: 平田 | C3: 島根県出雲市平田町7430番地 | D3: 0853-31-4622 | E3: 0853-62-1181 | H3: 株式会社シニアリビング・ネクスト | I3: 3270402393
A4: 特定施設入居者生活介護 ヴィラ湖水苑 | B4: 湖陵 | C4: 島根県出雲市湖陵町差海318－１ | D4: 0853-43-3950 | E4: 0853-43-3955 | F4: 40 | H4: 社会福祉法人壽光会 | I4: 3270402096 | J4: https://jukokai.jp/

Sheet 特定福祉用具販売
A1: 特定福祉用具販売（出雲市・19件）
A2: 事業所名 | B2: エリア | C2: 住所 | D2: 電話番号 | E2: FAX | F2: 定員 | G2: 営業日 | H2: 運営法人 | I2: 事業所番号 | J2: ホームページ | K2: 料金ページ
A3: あえる介護ショップ | B3: 出雲 | C3: 島根県出雲市西園町273-1 | D3: 0853-25-8921 | E3: 0853-25-8782 | G3: 平日 | H3: 株式会社ソーシャルプランニングネットワーク | I3: 3270400884 | J3: https://www.spn-web.jp/
A4: 出雲レンタル | B4: 出雲 | C4: 島根県出雲市天神町883-1三光ビル4号室三光ビル4号室 | D4: 0853-21-8001 | E4: 0853-21-8002 | G4: 平日 | H4: 株式会社神戸レンタル | I4: 3270403292
A5: 株式会社 歩夢 ケアショップ ももたろう | B5: 斐川 | C5: 出雲市斐川町直江4641-2 | D5: 0853-73-7130 | E5: 0853-73-7150 | G5: 平日 | H5: 株式会社歩夢 | I5: 3271600706
A6: 株式会社 こころ | B6: 斐川 | C6: 出雲市斐川町荘原3951 | D6: 0853-25-7564 | E6: 0853-25-7563 | G6: 平日,土曜日 | H6: 株式会社こころ | I6: 3271600672
A7: 株式会社 フルケア 山陰営業所 | B7: 出雲 | C7: 出雲市知井宮町１８５ | D7: 0853-20-1302 | E7: 0853-20-1303 | G7: 平日,土曜日 | H7: 株式会社フルケア | I7: 3270400819 | J7: https://www.full-care.jp/
A8: 株式会社イトガ | B8: 出雲 | C8: 島根県出雲市神西沖町１６８７－１１ | D8: 0853-43-1218 | E8: 0853-43-3450 | G8: 平日 | H8: 株式会社イトガ | I8: 3270401478
A9: (株)岩多屋福祉事業部出雲 | B9: 出雲 | C9: 島根県出雲市長浜町６５９－２１ | D9: 0853-27-0322 | E9: 0853-27-0320 | G9: 平日,祝日 | H9: 株式会社岩多屋 | I9: 3270402989 | J9: https://www.iwataya-net.co.jp/
A10: 株式会社原商 出雲事業所 | B10: 出雲 | C10: 島根県出雲市長浜町６５９－３９ | D10: 0853-28-3277 | E10: 0853-28-3288 | G10: 平日 | H10: 株式会社原商 | I10: 3270401627 | J10: https://www.harasho.co.jp/company/office/smile-care-office/smile-izumo
A11: 株式会社ホームケアー島根 | B11: 斐川 | C11: 島根県出雲市斐川町上直江2139-135 | D11: 0853-31-7878 | E11: 0853-72-0065 | G11: 平日,土曜日 | H11: 株式会社ホームケアー島根 | I11: 3270400017 | J11: http://www.homecare-shimane.jp/
A12: コニファー 株式会社 | B12: 出雲 | C12: 出雲市塩冶神前６-１-８ | D12: 0853-30-0528 | E12: 0853-30-0538 | G12: 平日,土曜日 | H12: コニファー 株式会社 | I12: 3270401544
A13: ジョイ・ケア たいよう | B13: 出雲 | C13: 出雲市荻杼町526-10 | D13: 0853-20-0670 | E13: 0853-20-0671 | G13: 平日,土曜日 | H13: 有限会社 Joy・ケア | I13: 3270400785 | J13: http://www.joycare.jp
A14: ダスキンヘルスレント島根東ステーション | B14: 出雲 | C14: 小山町333-1 | D14: 0853-25-7689 | E14: 0853-24-3164 | G14: 平日 | H14: 株式会社マサコーポレーション | I14: 3270402864 | J14: https://healthrent.duskin.jp/
A15: ハピネライフ一光 出雲支社 | B15: 出雲 | C15: 出雲市渡橋町418番地 | D15: 0853-23-6279 | E15: 0853-23-2267 | G15: 平日 | H15: 株式会社ハピネライフ一光 | I15: 3270400231 | J15: https://www.hapine.com/
A16: まるてい介護福祉事業所 | B16: 出雲 | C16: 出雲市白枝町４２７－４ | D16: 0853-20-1570 | E16: 0853-20-1571 | G16: 平日,土曜日 | H16: 有限会社エム・アール・シー | I16: 3270400587
A17: 有限会社出雲リハビリサービス | B17: 出雲 | C17: 島根県出雲市今市町547 | D17: 0853-22-3963 | E17: 0853-23-7578 | G17: 平日,土曜日 | H17: 有限会社出雲リハビリサービス | I17: 3270400702
A18: 有限会社 介護ショップもちだ | B18: 出雲 | C18: 出雲市矢尾町885-1 | D18: 0853-25-2016 | E18: 0853-25-2028 | G18: 平日 | H18: 有限会社 介護ショップもちだ | I18: 3270400389
A19: 有限会社 げんき堂 出雲営業所 | B19: 出雲 | C19: 島根県出雲市知井宮町185番地 | D19: 0853-20-1302 | E19: 0853-20-1303 | G19: 平日 | H19: 有限会社げんき堂 | I19: 3270403433 | J19: https://genkido-info.jimdofree.com/
A20: 有限会社アイライフ | B20: 出雲 | C20: 出雲市里方町893-5 | D20: 0853-23-6389 | E20: 0853-23-6325 | G20: 平日,土曜日 | H20: 有限会社アイライフ | I20: 3270400470
A21: ゆず | B21: 斐川 | C21: 島根県 出雲市 斐川町 神氷 2871 | D21: 0853-72-7209 | E21: 0853-72-7289 | G21: 平日 | H21: 株式会社 ゆず | I21: 3270402823 | J21: https://yuzu-izumo.com/

Sheet 居宅介護支援
A1: 居宅介護支援（出雲市・63件）
A2: 事業所名 | B2: エリア | C2: 住所 | D2: 電話番号 | E2: FAX | F2: 定員 | G2: 営業日 | H2: 運営法人 | I2: 事業所番号 | J2: ホームページ | K2: 料金ページ
A3: いきいきプラン居宅介護支援事業所 | B3: 平田 | C3: 島根県出雲市灘分町２２５－１７ | D3: 0853-62-0800 | E3: 0853-63-7771 | G3: 平日 | H3: 有限会社いきいきライフ | I3: 3270300258
A4: いこいの郷居宅介護支援事業所 | B4: 出雲 | C4: 島根県出雲市西林木町３３番地１いこいの郷いこいの郷 | D4: ０８５３－３１－５５３０ | E4: ０８５３－２１－６３５３ | G4: 平日 | H4: シルバーコミュニティセンター株式会社 | I4: 3270403078
A5: 石野居宅介護支援事業所 | B5: 出雲 | C5: 島根県出雲市稗原町２５２１番地５ケア・プラン石野合同会社ケア・プラン石野合同会社 | D5: 0853-48-2035 | E5: 0853-48-2035 | G5: 平日 | H5: ケア・プラン石野合同会社 | I5: 3270401734
A6: 出雲ケアセンターそよ風 | B6: 出雲 | C6: 島根県出雲市今市町876-9 | D6: 0853-20-0950 | E6: 0853-20-0956 | G6: 平日,祝日 | H6: 株式会社ＳＯＹＯＫＡＺＥ | I6: 3270401254
A7: 出雲市民病院 居宅介護支援事業所 | B7: 出雲 | C7: 出雲市今市町新町827-21在宅支援センター2階在宅支援センター2階 | D7: 0853-23-7370 | E7: 0853-23-7376 | G7: 平日 | H7: 出雲医療生活協同組合 | I7: 3210412528
A8: いなさ園居宅介護支援事業所 | B8: 大社 | C8: 出雲市大社町杵築西１６４３番地２ | D8: 0853-53-5727 | E8: 0853-53-5025 | G8: 平日 | H8: 社会福祉法人きづき会 | I8: 3271600078 | J8: http://www.kidukikai.or.jp
A9: うさぎケアプラン出雲 | B9: 出雲 | C9: 小山町３８５－５ | D9: 0853-25-8173 | E9: 0853-25-8174 | G9: 平日 | H9: 合同会社燦光 | I9: 3270402245
A10: うさぎケアプラン大社 | B10: 大社 | C10: 大社町北荒木211-4 | D10: 0853-53-3320 | E10: 0853-53-3330 | G10: 平日 | H10: 合同会社燦光 | I10: 3270403235
A11: ＮＰＯ法人たすけあい平田 | B11: 平田 | C11: 出雲市西代町１０３２-４ | D11: 0853-62-0257 | E11: 0853-62-0258 | G11: 平日 | H11: ＮＰＯ法人たすけあい平田 | I11: 3270300118 | J11: https://tasukeai-hirata.jp
A12: 介護の森山 | B12: 出雲 | C12: 荒茅町412番地 | D12: 090-2297-1675 | E12: 0853-25-7038 | G12: 平日 | H12: 介護の森山合同会社 | I12: 3270401684
A13: 居宅介護支援事業所 絆結 | B13: 斐川 | C13: 島根県出雲市斐川町鳥井691 | D13: 0853‐77‐6973 | E13: 0853‐77‐0486 | G13: 平日 | H13: 合同会社たいしゃＲｅ． | I13: 3270403417
A14: 居宅介護支援事業所 彩雲 | B14: 出雲 | C14: 島根県出雲市武志町755-1夢ハイツ107夢ハイツ107 | D14: 0853-25-8002 | E14: 0853-25-8228 | G14: 平日 | H14: 株式会社ラッシュ | I14: 3270403375
A15: 居宅介護支援事業所 成相 | B15: 出雲 | C15: 島根県出雲市上塩冶町234 | D15: 0853-25-8362 | E15: 0853-25-8363 | G15: 平日 | H15: 合同会社成相 | I15: 3270402856
A16: 居宅介護支援事業所 ライフコネクト | B16: 出雲 | C16: 島根県 出雲市 西園町273-1ライフサポートモール蒔庵内ライフサポートモール蒔庵内 | D16: 0853-25-8920 | E16: 0853-25-8782 | G16: 平日 | H16: 株式会社 ソーシャルプランニングネットワーク | I16: 3270403102
A17: 居宅介護支援事業所Gift | B17: 斐川 | C17: 島根県出雲市斐川町荘原2936番地1レジェンドひかわ103レジェンドひかわ103 | D17: 070-7665-1967 | E17: 050-3535-6724 | G17: 平日 | H17: 合同会社コスモ | I17: 3270403474 | J17: https://gift-izumo.jimdosite.com/
A18: 居宅介護支援事業所たんぽぽ | B18: 出雲 | C18: 島根県出雲市荒茅町２７８０－２８住宅型有料老人ホーム出雲すずかけの樹東棟住宅型有料老人ホーム出雲すずかけの樹東棟 | D18: ０８５３－２８－３６６６ | E18: ０８５３－２８－３６６７ | G18: 平日,土曜日,日曜日,祝日 | H18: 株式会社ライフサポート山陰 | I18: 3270402914
A19: 居宅介護支援事業所つなぐ | B19: 出雲 | C19: 島根県出雲市塩冶神前2丁目6-12コーポミスティ201コーポミスティ201 | D19: 0853-77-9543 | E19: 0853-77-9841 | G19: 平日 | H19: 合同会社ツナグ | I19: 3270403359
A20: 居宅介護支援事業所リンクス | B20: 出雲 | C20: 島根県出雲市小山町260-3ステージック2階ステージック2階 | D20: 0853-31-9791 | E20: 0853-31-9799 | G20: 平日 | H20: 合同会社リンクス | I20: 3270403052
A21: ケアサービスひらた | B21: 平田 | C21: 平田町698番地 | D21: 0853-63-3376 | E21: 0853-62-9114 | G21: 平日 | H21: 有限会社矢田商店 | I21: 3270401536 | J21: http://kyotaku.kaigodaiko.com/
A22: ケアプラン サン・スマイル | B22: 出雲 | C22: 島根県出雲市神西沖町215-1 | D22: 0853-43-2180 | E22: 0853-43-2300 | G22: 平日,土曜日,祝日 | H22: 社会福祉法人恵寿会 | I22: 3271600011 | J22: https://www.keijukai.jp/
A23: ケアプランあじさい | B23: 出雲 | C23: 島根県出雲市里方町８１２番地５ | D23: ０８５３－２７－９０８８ | E23: ０８５３－２７－９０８７ | G23: 平日 | H23: 合同会社ＲｅＬＩＦＥ出雲 | I23: 3270402997
A24: ケアプラン彩笑 | B24: 斐川 | C24: 島根県出雲市斐川町黒目1492-2 | D24: 0853-31-9485 | E24: 0853-31-9447 | G24: 平日 | H24: 合同会社プラン彩笑 | I24: 3270403334
A25: ケアプランセンター里庵 | B25: 平田 | C25: 島根県出雲市美野町504 | D25: 0853-67-9182 | E25: 0853-67-9183 | G25: 平日 | H25: 有限会社 伊野本陣 | I25: 3270403250 | J25: http://inohonjin.jp/
A26: CarePlanningこころ | B26: 出雲 | C26: 島根県出雲市天神町１１５番地２ | D26: ０８５３－３１－８８７７ | E26: ０８５３－２７－９１１４ | G26: 平日 | H26: 合同会社クオリティ・オブ・ライフ | I26: 3270403367
A27: ケアプラン向日葵の家 | B27: 斐川 | C27: 出雲市斐川町荘原3169番地28 | D27: 0853-72-5109 | E27: 0853-27-9737 | G27: 平日 | H27: 有限会社司 | I27: 3271600565
A28: ケアプラン松ぼっくり | B28: 斐川 | C28: 島根県出雲市斐川町神氷247番地 | D28: 0853-31-7601 | E28: 0853-31-7602 | G28: 平日 | H28: 合同会社共生乃大福 | I28: 3270403466
A29: ケアプランやわらぎ | B29: 出雲 | C29: 島根県出雲市知井宮町1192-9 | D29: 0853-21-4820 | E29: 0853-21-7280 | G29: 平日 | H29: 株式会社ケアステーションやわらぎ | I29: 3270402278
A30: 合同会社 社会福祉支援ちいろば | B30: 大社 | C30: 出雲市大社町北荒木1369 | D30: 0853－31－4309 | E30: 0853－31－5988 | G30: 平日 | H30: 合同会社社会福祉支援ちいろば | I30: 3270403110
A31: サンキ・ウエルビィ介護センター出雲 | B31: 出雲 | C31: 島根県出雲市浜町96-1 | D31: 0853-20-7495 | E31: 0853-20-7497 | G31: 平日 | H31: サンキ・ウエルビィ株式会社 | I31: 3270400454
A32: しあわせぞうさん | B32: 大社 | C32: 島根県出雲市大社町遙堪663-25 | D32: 050-8893-1122 | E32: 050-1799-0234 | G32: 平日 | H32: 合同会社しあわせぞうさん | I32: 3270403482
A33: 指定居宅介護支援事業所えがおライフ川光（大社） | B33: 出雲 | C33: 島根県出雲市平野町1116番地4 | D33: 0853-31-4445 | E33: 0853-31-4446 | G33: 平日 | H33: 株式会社えがおライフ島根 | I33: 3270403326 | J33: http://smile-life-kawamitsu.jp
A34: 指定居宅介護支援事業所エスポアール | B34: 出雲 | C34: 出雲市小山町３６2－1 | D34: 0853-21-9779 | E34: 0853-21-9780 | G34: 平日 | H34: 医療法人エスポアール出雲クリニック | I34: 3270401064 | J34: http://www.espoir-izumo.or.jp
A35: ＪＡしまね斐川介護センター | B35: 斐川 | C35: 島根県出雲市斐川町荘原2172番地3 | D35: 0853-73-9635 | E35: 0853-73-9636 | G35: 平日 | H35: 島根県農業協同組合 | I35: 3270402575 | J35: https://ja-shimane.jp/
A36: 寿生在宅介護相談センター | B36: 出雲 | C36: 出雲市上塩冶町2862-1 | D36: 0853-24-2321 | E36: 0853-25-0267 | G36: 平日 | H36: 壽生会 | I36: 3270400207 | J36: http://www.juseikai.jp/
A37: 清流園在宅介護支援センター | B37: 出雲 | C37: 島根県出雲市大津町3529番地 | D37: 0853-21-9333 | E37: 0853-20-7086 | G37: 平日 | H37: 社会福祉法人静和会 | I37: 3270400033
A38: 高鳥クリニック地域リハビリテーションセンター 居宅介護支援事業所 | B38: 出雲 | C38: 島根県出雲市武志町７３４－１ | D38: 0853-20-1338 | E38: 0853-24-8515 | G38: 平日 | H38: 医療法人社団岡倉会 | I38: 3260490044
A39: たき居宅介護支援事業所 | B39: 多伎 | C39: 出雲市多伎町小田50－3 | D39: 0853-86-2612 | E39: 0853-86-2972 | G39: 平日,土曜日 | H39: 社会福祉法人多伎の郷 | I39: 3271600029 | J39: https://www.takinosato.jp/
A40: デイサービス金太郎の家 | B40: 斐川 | C40: 島根県出雲市斐川町学頭1463-10 | D40: 0853-27-9567 | E40: 0853-72-5192 | G40: 平日,土曜日,祝日 | H40: 社会福祉法人金太郎の家 | I40: 3270402476 | J40: https://www.kintarounoie.jp
...

Sheet 介護老人福祉施設
A1: 介護老人福祉施設（出雲市・18件）
A2: 事業所名 | B2: エリア | C2: 住所 | D2: 電話番号 | E2: FAX | F2: 定員 | G2: 営業日 | H2: 運営法人 | I2: 事業所番号 | J2: ホームページ | K2: 料金ページ
A3: 特別養護老人ホーム いなさ園 | B3: 大社 | C3: 島根県出雲市大社町杵築西１６４３番地２ | D3: 0853-53-5727 | E3: 0853-53-5025 | F3: 80 | H3: 社会福祉法人きづき会 | I3: 3271690038 | J3: http://www.kidukikai.or.jp
A4: 特別養護老人ホーム かんべの里 | B4: 斐川 | C4: 島根県出雲市斐川町名島93番地2 | D4: 0853-72-3097 | E4: 0853-72-3190 | F4: 40 | H4: 社会福祉法人 喜和会 | I4: 3271690079 | J4: https://taiyounosato.or.jp/
A5: 特別養護老人ホーム 湖水苑 | B5: 湖陵 | C5: 島根県出雲市湖陵町差海318-1 | D5: 0853-43-8955 | E5: 0853-43-0995 | F5: 80 | H5: 社会福祉法人壽光会 | I5: 3271690061 | J5: https://jukokai.jp/
